2018-06-28 16:02:00,326 [Dummy-1:139975913236224] [django.db.backends:91] [utils:execute] [DEBUG]- (0.002) SELECT @@SQL_AUTO_IS_NULL; args=None
2018-06-28 16:02:00,329 [Dummy-1:139975913236224] [django.db.backends:91] [utils:execute] [DEBUG]- (0.002) SELECT VERSION(); args=None
2018-06-28 16:02:00,360 [Dummy-1:139975913236224] [django.db.backends:91] [utils:execute] [DEBUG]- (0.002) SHOW FULL TABLES; args=None
2018-06-28 16:02:00,378 [Dummy-1:139975913236224] [django.db.backends:91] [utils:execute] [DEBUG]- (0.002) SELECT `django_migrations`.`app`, `django_migrations`.`name` FROM `django_migrations`; args=()
2018-06-28 16:02:01,412 [Thread-3:139975893231360] [django:44] [views:test_log] [WARNING]- thi is python 1906
2018-06-28 16:02:01,413 [Thread-3:139975893231360] [django.server:124] [basehttp:log_message] [INFO]- "GET /testlog HTTP/1.1" 200 2
2018-06-28 21:24:08,712 [Dummy-1:139660296488704] [django.db.backends:91] [utils:execute] [DEBUG]- (0.002) SELECT @@SQL_AUTO_IS_NULL; args=None
2018-06-28 21:24:08,715 [Dummy-1:139660296488704] [django.db.backends:91] [utils:execute] [DEBUG]- (0.002) SELECT VERSION(); args=None
2018-06-28 21:24:08,746 [Dummy-1:139660296488704] [django.db.backends:91] [utils:execute] [DEBUG]- (0.002) SHOW FULL TABLES; args=None
2018-06-28 21:24:08,768 [Dummy-1:139660296488704] [django.db.backends:91] [utils:execute] [DEBUG]- (0.002) SELECT `django_migrations`.`app`, `django_migrations`.`name` FROM `django_migrations`; args=()
2018-06-28 21:24:13,345 [Thread-3:139660276483840] [django.request:135] [exception:handle_uncaught_exception] [ERROR]- Internal Server Error: /email
Traceback (most recent call last):
  File "/usr/local/lib/python3.5/dist-packages/django/core/handlers/exception.py", line 41, in inner
    response = get_response(request)
  File "/usr/local/lib/python3.5/dist-packages/django/core/handlers/base.py", line 187, in _get_response
    response = self.process_exception_by_middleware(e, request)
  File "/usr/local/lib/python3.5/dist-packages/django/core/handlers/base.py", line 185, in _get_response
    response = wrapped_callback(request, *callback_args, **callback_kwargs)
  File "/root/teach1806/day08/t8/views.py", line 39, in send_my_mail
    msg.send()
  File "/usr/local/lib/python3.5/dist-packages/django/core/mail/message.py", line 348, in send
    return self.get_connection(fail_silently).send_messages([self])
  File "/usr/local/lib/python3.5/dist-packages/django/core/mail/backends/smtp.py", line 104, in send_messages
    new_conn_created = self.open()
  File "/usr/local/lib/python3.5/dist-packages/django/core/mail/backends/smtp.py", line 71, in open
    self.connection.login(force_str(self.username), force_str(self.password))
  File "/usr/lib/python3.5/smtplib.py", line 729, in login
    raise last_exception
  File "/usr/lib/python3.5/smtplib.py", line 720, in login
    initial_response_ok=initial_response_ok)
  File "/usr/lib/python3.5/smtplib.py", line 641, in auth
    raise SMTPAuthenticationError(code, resp)
smtplib.SMTPAuthenticationError: (535, b'Error: \xc7\xeb\xca\xb9\xd3\xc3\xca\xda\xc8\xa8\xc2\xeb\xb5\xc7\xc2\xbc\xa1\xa3\xcf\xea\xc7\xe9\xc7\xeb\xbf\xb4: http://service.mail.qq.com/cgi-bin/help?subtype=1&&id=28&&no=1001256')
2018-06-28 21:24:13,345 [Thread-3:139660276483840] [django.request:135] [exception:handle_uncaught_exception] [ERROR]- Internal Server Error: /email
Traceback (most recent call last):
  File "/usr/local/lib/python3.5/dist-packages/django/core/handlers/exception.py", line 41, in inner
    response = get_response(request)
  File "/usr/local/lib/python3.5/dist-packages/django/core/handlers/base.py", line 187, in _get_response
    response = self.process_exception_by_middleware(e, request)
  File "/usr/local/lib/python3.5/dist-packages/django/core/handlers/base.py", line 185, in _get_response
    response = wrapped_callback(request, *callback_args, **callback_kwargs)
  File "/root/teach1806/day08/t8/views.py", line 39, in send_my_mail
    msg.send()
  File "/usr/local/lib/python3.5/dist-packages/django/core/mail/message.py", line 348, in send
    return self.get_connection(fail_silently).send_messages([self])
  File "/usr/local/lib/python3.5/dist-packages/django/core/mail/backends/smtp.py", line 104, in send_messages
    new_conn_created = self.open()
  File "/usr/local/lib/python3.5/dist-packages/django/core/mail/backends/smtp.py", line 71, in open
    self.connection.login(force_str(self.username), force_str(self.password))
  File "/usr/lib/python3.5/smtplib.py", line 729, in login
    raise last_exception
  File "/usr/lib/python3.5/smtplib.py", line 720, in login
    initial_response_ok=initial_response_ok)
  File "/usr/lib/python3.5/smtplib.py", line 641, in auth
    raise SMTPAuthenticationError(code, resp)
smtplib.SMTPAuthenticationError: (535, b'Error: \xc7\xeb\xca\xb9\xd3\xc3\xca\xda\xc8\xa8\xc2\xeb\xb5\xc7\xc2\xbc\xa1\xa3\xcf\xea\xc7\xe9\xc7\xeb\xbf\xb4: http://service.mail.qq.com/cgi-bin/help?subtype=1&&id=28&&no=1001256')
2018-06-28 21:24:13,422 [Thread-3:139660276483840] [django.server:124] [basehttp:log_message] [ERROR]- "GET /email HTTP/1.1" 500 97396
2018-06-28 21:24:13,770 [Thread-2:139660284876544] [django.template:925] [base:_resolve_lookup] [DEBUG]- Exception while resolving variable 'name' in template 'unknown'.
Traceback (most recent call last):
  File "/usr/local/lib/python3.5/dist-packages/django/core/handlers/exception.py", line 41, in inner
    response = get_response(request)
  File "/usr/local/lib/python3.5/dist-packages/django/core/handlers/base.py", line 172, in _get_response
    resolver_match = resolver.resolve(request.path_info)
  File "/usr/local/lib/python3.5/dist-packages/django/urls/resolvers.py", line 392, in resolve
    raise Resolver404({'tried': tried, 'path': new_path})
django.urls.exceptions.Resolver404: {'tried': [[<RegexURLResolver <RegexURLPattern list> (admin:admin) ^admin/>], [<RegexURLPattern None ^email$>], [<RegexURLPattern None ^htmlems$>], [<RegexURLPattern None ^test$>], [<RegexURLPattern None ^verify/(.+)>], [<RegexURLPattern None ^testlog$>]], 'path': 'favicon.ico'}

During handling of the above exception, another exception occurred:

Traceback (most recent call last):
  File "/usr/local/lib/python3.5/dist-packages/django/template/base.py", line 882, in _resolve_lookup
    current = current[bit]
TypeError: 'RegexURLResolver' object is not subscriptable

During handling of the above exception, another exception occurred:

Traceback (most recent call last):
  File "/usr/local/lib/python3.5/dist-packages/django/template/base.py", line 890, in _resolve_lookup
    current = getattr(current, bit)
AttributeError: 'RegexURLResolver' object has no attribute 'name'

During handling of the above exception, another exception occurred:

Traceback (most recent call last):
  File "/usr/local/lib/python3.5/dist-packages/django/template/base.py", line 896, in _resolve_lookup
    current = current[int(bit)]
ValueError: invalid literal for int() with base 10: 'name'

During handling of the above exception, another exception occurred:

Traceback (most recent call last):
  File "/usr/local/lib/python3.5/dist-packages/django/template/base.py", line 903, in _resolve_lookup
    (bit, current))  # missing attribute
django.template.base.VariableDoesNotExist: Failed lookup for key [name] in '<RegexURLResolver <RegexURLPattern list> (admin:admin) ^admin/>'
2018-06-28 21:24:13,772 [Thread-2:139660284876544] [django.server:124] [basehttp:log_message] [WARNING]- "GET /favicon.ico HTTP/1.1" 404 2510
2018-06-28 21:24:20,773 [Thread-4:139660284876544] [django.template:925] [base:_resolve_lookup] [DEBUG]- Exception while resolving variable 'name' in template 'unknown'.
Traceback (most recent call last):
  File "/usr/local/lib/python3.5/dist-packages/django/core/handlers/exception.py", line 41, in inner
    response = get_response(request)
  File "/usr/local/lib/python3.5/dist-packages/django/core/handlers/base.py", line 172, in _get_response
    resolver_match = resolver.resolve(request.path_info)
  File "/usr/local/lib/python3.5/dist-packages/django/urls/resolvers.py", line 392, in resolve
    raise Resolver404({'tried': tried, 'path': new_path})
django.urls.exceptions.Resolver404: {'tried': [[<RegexURLResolver <RegexURLPattern list> (admin:admin) ^admin/>], [<RegexURLPattern None ^email$>], [<RegexURLPattern None ^htmlems$>], [<RegexURLPattern None ^test$>], [<RegexURLPattern None ^verify/(.+)>], [<RegexURLPattern None ^testlog$>]], 'path': 'email——from'}

During handling of the above exception, another exception occurred:

Traceback (most recent call last):
  File "/usr/local/lib/python3.5/dist-packages/django/template/base.py", line 882, in _resolve_lookup
    current = current[bit]
TypeError: 'RegexURLResolver' object is not subscriptable

During handling of the above exception, another exception occurred:

Traceback (most recent call last):
  File "/usr/local/lib/python3.5/dist-packages/django/template/base.py", line 890, in _resolve_lookup
    current = getattr(current, bit)
AttributeError: 'RegexURLResolver' object has no attribute 'name'

During handling of the above exception, another exception occurred:

Traceback (most recent call last):
  File "/usr/local/lib/python3.5/dist-packages/django/template/base.py", line 896, in _resolve_lookup
    current = current[int(bit)]
ValueError: invalid literal for int() with base 10: 'name'

During handling of the above exception, another exception occurred:

Traceback (most recent call last):
  File "/usr/local/lib/python3.5/dist-packages/django/template/base.py", line 903, in _resolve_lookup
    (bit, current))  # missing attribute
django.template.base.VariableDoesNotExist: Failed lookup for key [name] in '<RegexURLResolver <RegexURLPattern list> (admin:admin) ^admin/>'
2018-06-28 21:24:20,776 [Thread-4:139660284876544] [django.server:124] [basehttp:log_message] [WARNING]- "GET /email%E2%80%94%E2%80%94from HTTP/1.1" 404 2534
2018-06-28 21:24:27,724 [Thread-5:139660276483840] [django.template:925] [base:_resolve_lookup] [DEBUG]- Exception while resolving variable 'name' in template 'unknown'.
Traceback (most recent call last):
  File "/usr/local/lib/python3.5/dist-packages/django/core/handlers/exception.py", line 41, in inner
    response = get_response(request)
  File "/usr/local/lib/python3.5/dist-packages/django/core/handlers/base.py", line 172, in _get_response
    resolver_match = resolver.resolve(request.path_info)
  File "/usr/local/lib/python3.5/dist-packages/django/urls/resolvers.py", line 392, in resolve
    raise Resolver404({'tried': tried, 'path': new_path})
django.urls.exceptions.Resolver404: {'tried': [[<RegexURLResolver <RegexURLPattern list> (admin:admin) ^admin/>], [<RegexURLPattern None ^email$>], [<RegexURLPattern None ^htmlems$>], [<RegexURLPattern None ^test$>], [<RegexURLPattern None ^verify/(.+)>], [<RegexURLPattern None ^testlog$>]], 'path': 'email_from'}

During handling of the above exception, another exception occurred:

Traceback (most recent call last):
  File "/usr/local/lib/python3.5/dist-packages/django/template/base.py", line 882, in _resolve_lookup
    current = current[bit]
TypeError: 'RegexURLResolver' object is not subscriptable

During handling of the above exception, another exception occurred:

Traceback (most recent call last):
  File "/usr/local/lib/python3.5/dist-packages/django/template/base.py", line 890, in _resolve_lookup
    current = getattr(current, bit)
AttributeError: 'RegexURLResolver' object has no attribute 'name'

During handling of the above exception, another exception occurred:

Traceback (most recent call last):
  File "/usr/local/lib/python3.5/dist-packages/django/template/base.py", line 896, in _resolve_lookup
    current = current[int(bit)]
ValueError: invalid literal for int() with base 10: 'name'

During handling of the above exception, another exception occurred:

Traceback (most recent call last):
  File "/usr/local/lib/python3.5/dist-packages/django/template/base.py", line 903, in _resolve_lookup
    (bit, current))  # missing attribute
django.template.base.VariableDoesNotExist: Failed lookup for key [name] in '<RegexURLResolver <RegexURLPattern list> (admin:admin) ^admin/>'
2018-06-28 21:24:27,727 [Thread-5:139660276483840] [django.server:124] [basehttp:log_message] [WARNING]- "GET /email_from HTTP/1.1" 404 2507
2018-06-28 21:26:29,273 [Dummy-1:140153377236736] [django.db.backends:91] [utils:execute] [DEBUG]- (0.003) SELECT @@SQL_AUTO_IS_NULL; args=None
2018-06-28 21:26:29,276 [Dummy-1:140153377236736] [django.db.backends:91] [utils:execute] [DEBUG]- (0.003) SELECT VERSION(); args=None
2018-06-28 21:26:29,307 [Dummy-1:140153377236736] [django.db.backends:91] [utils:execute] [DEBUG]- (0.002) SHOW FULL TABLES; args=None
2018-06-28 21:26:29,326 [Dummy-1:140153377236736] [django.db.backends:91] [utils:execute] [DEBUG]- (0.002) SELECT `django_migrations`.`app`, `django_migrations`.`name` FROM `django_migrations`; args=()
2018-06-28 21:27:10,285 [Thread-2:140153365624576] [django.request:135] [exception:handle_uncaught_exception] [ERROR]- Internal Server Error: /email
Traceback (most recent call last):
  File "/usr/local/lib/python3.5/dist-packages/django/core/handlers/exception.py", line 41, in inner
    response = get_response(request)
  File "/usr/local/lib/python3.5/dist-packages/django/core/handlers/base.py", line 187, in _get_response
    response = self.process_exception_by_middleware(e, request)
  File "/usr/local/lib/python3.5/dist-packages/django/core/handlers/base.py", line 185, in _get_response
    response = wrapped_callback(request, *callback_args, **callback_kwargs)
  File "/root/teach1806/day08/t8/views.py", line 39, in send_my_mail
    msg.send()
  File "/usr/local/lib/python3.5/dist-packages/django/core/mail/message.py", line 348, in send
    return self.get_connection(fail_silently).send_messages([self])
  File "/usr/local/lib/python3.5/dist-packages/django/core/mail/backends/smtp.py", line 104, in send_messages
    new_conn_created = self.open()
  File "/usr/local/lib/python3.5/dist-packages/django/core/mail/backends/smtp.py", line 71, in open
    self.connection.login(force_str(self.username), force_str(self.password))
  File "/usr/lib/python3.5/smtplib.py", line 729, in login
    raise last_exception
  File "/usr/lib/python3.5/smtplib.py", line 720, in login
    initial_response_ok=initial_response_ok)
  File "/usr/lib/python3.5/smtplib.py", line 641, in auth
    raise SMTPAuthenticationError(code, resp)
smtplib.SMTPAuthenticationError: (535, b'Error: \xc7\xeb\xca\xb9\xd3\xc3\xca\xda\xc8\xa8\xc2\xeb\xb5\xc7\xc2\xbc\xa1\xa3\xcf\xea\xc7\xe9\xc7\xeb\xbf\xb4: http://service.mail.qq.com/cgi-bin/help?subtype=1&&id=28&&no=1001256')
2018-06-28 21:27:10,285 [Thread-2:140153365624576] [django.request:135] [exception:handle_uncaught_exception] [ERROR]- Internal Server Error: /email
Traceback (most recent call last):
  File "/usr/local/lib/python3.5/dist-packages/django/core/handlers/exception.py", line 41, in inner
    response = get_response(request)
  File "/usr/local/lib/python3.5/dist-packages/django/core/handlers/base.py", line 187, in _get_response
    response = self.process_exception_by_middleware(e, request)
  File "/usr/local/lib/python3.5/dist-packages/django/core/handlers/base.py", line 185, in _get_response
    response = wrapped_callback(request, *callback_args, **callback_kwargs)
  File "/root/teach1806/day08/t8/views.py", line 39, in send_my_mail
    msg.send()
  File "/usr/local/lib/python3.5/dist-packages/django/core/mail/message.py", line 348, in send
    return self.get_connection(fail_silently).send_messages([self])
  File "/usr/local/lib/python3.5/dist-packages/django/core/mail/backends/smtp.py", line 104, in send_messages
    new_conn_created = self.open()
  File "/usr/local/lib/python3.5/dist-packages/django/core/mail/backends/smtp.py", line 71, in open
    self.connection.login(force_str(self.username), force_str(self.password))
  File "/usr/lib/python3.5/smtplib.py", line 729, in login
    raise last_exception
  File "/usr/lib/python3.5/smtplib.py", line 720, in login
    initial_response_ok=initial_response_ok)
  File "/usr/lib/python3.5/smtplib.py", line 641, in auth
    raise SMTPAuthenticationError(code, resp)
smtplib.SMTPAuthenticationError: (535, b'Error: \xc7\xeb\xca\xb9\xd3\xc3\xca\xda\xc8\xa8\xc2\xeb\xb5\xc7\xc2\xbc\xa1\xa3\xcf\xea\xc7\xe9\xc7\xeb\xbf\xb4: http://service.mail.qq.com/cgi-bin/help?subtype=1&&id=28&&no=1001256')
2018-06-28 21:27:10,338 [Thread-2:140153365624576] [django.server:124] [basehttp:log_message] [ERROR]- "GET /email HTTP/1.1" 500 97261
2018-06-28 21:27:46,256 [Dummy-1:139857096926976] [django.db.backends:91] [utils:execute] [DEBUG]- (0.002) SELECT @@SQL_AUTO_IS_NULL; args=None
2018-06-28 21:27:46,259 [Dummy-1:139857096926976] [django.db.backends:91] [utils:execute] [DEBUG]- (0.002) SELECT VERSION(); args=None
2018-06-28 21:27:46,294 [Dummy-1:139857096926976] [django.db.backends:91] [utils:execute] [DEBUG]- (0.003) SHOW FULL TABLES; args=None
2018-06-28 21:27:46,314 [Dummy-1:139857096926976] [django.db.backends:91] [utils:execute] [DEBUG]- (0.003) SELECT `django_migrations`.`app`, `django_migrations`.`name` FROM `django_migrations`; args=()
2018-06-28 21:27:50,582 [Thread-2:139857017886464] [django.request:135] [exception:handle_uncaught_exception] [ERROR]- Internal Server Error: /email
Traceback (most recent call last):
  File "/usr/local/lib/python3.5/dist-packages/django/core/handlers/exception.py", line 41, in inner
    response = get_response(request)
  File "/usr/local/lib/python3.5/dist-packages/django/core/handlers/base.py", line 187, in _get_response
    response = self.process_exception_by_middleware(e, request)
  File "/usr/local/lib/python3.5/dist-packages/django/core/handlers/base.py", line 185, in _get_response
    response = wrapped_callback(request, *callback_args, **callback_kwargs)
  File "/root/teach1806/day08/t8/views.py", line 39, in send_my_mail
    msg.send()
  File "/usr/local/lib/python3.5/dist-packages/django/core/mail/message.py", line 348, in send
    return self.get_connection(fail_silently).send_messages([self])
  File "/usr/local/lib/python3.5/dist-packages/django/core/mail/backends/smtp.py", line 104, in send_messages
    new_conn_created = self.open()
  File "/usr/local/lib/python3.5/dist-packages/django/core/mail/backends/smtp.py", line 71, in open
    self.connection.login(force_str(self.username), force_str(self.password))
  File "/usr/lib/python3.5/smtplib.py", line 729, in login
    raise last_exception
  File "/usr/lib/python3.5/smtplib.py", line 720, in login
    initial_response_ok=initial_response_ok)
  File "/usr/lib/python3.5/smtplib.py", line 641, in auth
    raise SMTPAuthenticationError(code, resp)
smtplib.SMTPAuthenticationError: (535, b'Error: \xc7\xeb\xca\xb9\xd3\xc3\xca\xda\xc8\xa8\xc2\xeb\xb5\xc7\xc2\xbc\xa1\xa3\xcf\xea\xc7\xe9\xc7\xeb\xbf\xb4: http://service.mail.qq.com/cgi-bin/help?subtype=1&&id=28&&no=1001256')
2018-06-28 21:27:50,582 [Thread-2:139857017886464] [django.request:135] [exception:handle_uncaught_exception] [ERROR]- Internal Server Error: /email
Traceback (most recent call last):
  File "/usr/local/lib/python3.5/dist-packages/django/core/handlers/exception.py", line 41, in inner
    response = get_response(request)
  File "/usr/local/lib/python3.5/dist-packages/django/core/handlers/base.py", line 187, in _get_response
    response = self.process_exception_by_middleware(e, request)
  File "/usr/local/lib/python3.5/dist-packages/django/core/handlers/base.py", line 185, in _get_response
    response = wrapped_callback(request, *callback_args, **callback_kwargs)
  File "/root/teach1806/day08/t8/views.py", line 39, in send_my_mail
    msg.send()
  File "/usr/local/lib/python3.5/dist-packages/django/core/mail/message.py", line 348, in send
    return self.get_connection(fail_silently).send_messages([self])
  File "/usr/local/lib/python3.5/dist-packages/django/core/mail/backends/smtp.py", line 104, in send_messages
    new_conn_created = self.open()
  File "/usr/local/lib/python3.5/dist-packages/django/core/mail/backends/smtp.py", line 71, in open
    self.connection.login(force_str(self.username), force_str(self.password))
  File "/usr/lib/python3.5/smtplib.py", line 729, in login
    raise last_exception
  File "/usr/lib/python3.5/smtplib.py", line 720, in login
    initial_response_ok=initial_response_ok)
  File "/usr/lib/python3.5/smtplib.py", line 641, in auth
    raise SMTPAuthenticationError(code, resp)
smtplib.SMTPAuthenticationError: (535, b'Error: \xc7\xeb\xca\xb9\xd3\xc3\xca\xda\xc8\xa8\xc2\xeb\xb5\xc7\xc2\xbc\xa1\xa3\xcf\xea\xc7\xe9\xc7\xeb\xbf\xb4: http://service.mail.qq.com/cgi-bin/help?subtype=1&&id=28&&no=1001256')
2018-06-28 21:27:50,662 [Thread-2:139857017886464] [django.server:124] [basehttp:log_message] [ERROR]- "GET /email HTTP/1.1" 500 97396
2018-06-28 21:28:40,066 [Dummy-1:140342237173504] [django.db.backends:91] [utils:execute] [DEBUG]- (0.002) SELECT @@SQL_AUTO_IS_NULL; args=None
2018-06-28 21:28:40,069 [Dummy-1:140342237173504] [django.db.backends:91] [utils:execute] [DEBUG]- (0.002) SELECT VERSION(); args=None
2018-06-28 21:28:40,103 [Dummy-1:140342237173504] [django.db.backends:91] [utils:execute] [DEBUG]- (0.002) SHOW FULL TABLES; args=None
2018-06-28 21:28:40,124 [Dummy-1:140342237173504] [django.db.backends:91] [utils:execute] [DEBUG]- (0.003) SELECT `django_migrations`.`app`, `django_migrations`.`name` FROM `django_migrations`; args=()
2018-06-28 21:28:44,538 [Thread-2:140342225561344] [django.request:135] [exception:handle_uncaught_exception] [ERROR]- Internal Server Error: /email
Traceback (most recent call last):
  File "/usr/local/lib/python3.5/dist-packages/django/core/handlers/exception.py", line 41, in inner
    response = get_response(request)
  File "/usr/local/lib/python3.5/dist-packages/django/core/handlers/base.py", line 187, in _get_response
    response = self.process_exception_by_middleware(e, request)
  File "/usr/local/lib/python3.5/dist-packages/django/core/handlers/base.py", line 185, in _get_response
    response = wrapped_callback(request, *callback_args, **callback_kwargs)
  File "/root/teach1806/day08/t8/views.py", line 39, in send_my_mail
    msg.send()
  File "/usr/local/lib/python3.5/dist-packages/django/core/mail/message.py", line 348, in send
    return self.get_connection(fail_silently).send_messages([self])
  File "/usr/local/lib/python3.5/dist-packages/django/core/mail/backends/smtp.py", line 104, in send_messages
    new_conn_created = self.open()
  File "/usr/local/lib/python3.5/dist-packages/django/core/mail/backends/smtp.py", line 71, in open
    self.connection.login(force_str(self.username), force_str(self.password))
  File "/usr/lib/python3.5/smtplib.py", line 729, in login
    raise last_exception
  File "/usr/lib/python3.5/smtplib.py", line 720, in login
    initial_response_ok=initial_response_ok)
  File "/usr/lib/python3.5/smtplib.py", line 641, in auth
    raise SMTPAuthenticationError(code, resp)
smtplib.SMTPAuthenticationError: (535, b'Error: \xc7\xeb\xca\xb9\xd3\xc3\xca\xda\xc8\xa8\xc2\xeb\xb5\xc7\xc2\xbc\xa1\xa3\xcf\xea\xc7\xe9\xc7\xeb\xbf\xb4: http://service.mail.qq.com/cgi-bin/help?subtype=1&&id=28&&no=1001256')
2018-06-28 21:28:44,538 [Thread-2:140342225561344] [django.request:135] [exception:handle_uncaught_exception] [ERROR]- Internal Server Error: /email
Traceback (most recent call last):
  File "/usr/local/lib/python3.5/dist-packages/django/core/handlers/exception.py", line 41, in inner
    response = get_response(request)
  File "/usr/local/lib/python3.5/dist-packages/django/core/handlers/base.py", line 187, in _get_response
    response = self.process_exception_by_middleware(e, request)
  File "/usr/local/lib/python3.5/dist-packages/django/core/handlers/base.py", line 185, in _get_response
    response = wrapped_callback(request, *callback_args, **callback_kwargs)
  File "/root/teach1806/day08/t8/views.py", line 39, in send_my_mail
    msg.send()
  File "/usr/local/lib/python3.5/dist-packages/django/core/mail/message.py", line 348, in send
    return self.get_connection(fail_silently).send_messages([self])
  File "/usr/local/lib/python3.5/dist-packages/django/core/mail/backends/smtp.py", line 104, in send_messages
    new_conn_created = self.open()
  File "/usr/local/lib/python3.5/dist-packages/django/core/mail/backends/smtp.py", line 71, in open
    self.connection.login(force_str(self.username), force_str(self.password))
  File "/usr/lib/python3.5/smtplib.py", line 729, in login
    raise last_exception
  File "/usr/lib/python3.5/smtplib.py", line 720, in login
    initial_response_ok=initial_response_ok)
  File "/usr/lib/python3.5/smtplib.py", line 641, in auth
    raise SMTPAuthenticationError(code, resp)
smtplib.SMTPAuthenticationError: (535, b'Error: \xc7\xeb\xca\xb9\xd3\xc3\xca\xda\xc8\xa8\xc2\xeb\xb5\xc7\xc2\xbc\xa1\xa3\xcf\xea\xc7\xe9\xc7\xeb\xbf\xb4: http://service.mail.qq.com/cgi-bin/help?subtype=1&&id=28&&no=1001256')
2018-06-28 21:28:44,600 [Thread-2:140342225561344] [django.server:124] [basehttp:log_message] [ERROR]- "GET /email HTTP/1.1" 500 97396
2018-06-28 21:34:28,135 [Dummy-1:140082199758592] [django.db.backends:91] [utils:execute] [DEBUG]- (0.002) SELECT @@SQL_AUTO_IS_NULL; args=None
2018-06-28 21:34:28,138 [Dummy-1:140082199758592] [django.db.backends:91] [utils:execute] [DEBUG]- (0.002) SELECT VERSION(); args=None
2018-06-28 21:34:28,169 [Dummy-1:140082199758592] [django.db.backends:91] [utils:execute] [DEBUG]- (0.003) SHOW FULL TABLES; args=None
2018-06-28 21:34:28,188 [Dummy-1:140082199758592] [django.db.backends:91] [utils:execute] [DEBUG]- (0.003) SELECT `django_migrations`.`app`, `django_migrations`.`name` FROM `django_migrations`; args=()
2018-06-28 21:34:32,626 [Thread-2:140082188146432] [django.request:135] [exception:handle_uncaught_exception] [ERROR]- Internal Server Error: /email
Traceback (most recent call last):
  File "/usr/local/lib/python3.5/dist-packages/django/core/handlers/exception.py", line 41, in inner
    response = get_response(request)
  File "/usr/local/lib/python3.5/dist-packages/django/core/handlers/base.py", line 187, in _get_response
    response = self.process_exception_by_middleware(e, request)
  File "/usr/local/lib/python3.5/dist-packages/django/core/handlers/base.py", line 185, in _get_response
    response = wrapped_callback(request, *callback_args, **callback_kwargs)
  File "/root/teach1806/day08/t8/views.py", line 39, in send_my_mail
    msg.send()
  File "/usr/local/lib/python3.5/dist-packages/django/core/mail/message.py", line 348, in send
    return self.get_connection(fail_silently).send_messages([self])
  File "/usr/local/lib/python3.5/dist-packages/django/core/mail/backends/smtp.py", line 104, in send_messages
    new_conn_created = self.open()
  File "/usr/local/lib/python3.5/dist-packages/django/core/mail/backends/smtp.py", line 71, in open
    self.connection.login(force_str(self.username), force_str(self.password))
  File "/usr/lib/python3.5/smtplib.py", line 729, in login
    raise last_exception
  File "/usr/lib/python3.5/smtplib.py", line 720, in login
    initial_response_ok=initial_response_ok)
  File "/usr/lib/python3.5/smtplib.py", line 641, in auth
    raise SMTPAuthenticationError(code, resp)
smtplib.SMTPAuthenticationError: (535, b'Error: \xc7\xeb\xca\xb9\xd3\xc3\xca\xda\xc8\xa8\xc2\xeb\xb5\xc7\xc2\xbc\xa1\xa3\xcf\xea\xc7\xe9\xc7\xeb\xbf\xb4: http://service.mail.qq.com/cgi-bin/help?subtype=1&&id=28&&no=1001256')
2018-06-28 21:34:32,626 [Thread-2:140082188146432] [django.request:135] [exception:handle_uncaught_exception] [ERROR]- Internal Server Error: /email
Traceback (most recent call last):
  File "/usr/local/lib/python3.5/dist-packages/django/core/handlers/exception.py", line 41, in inner
    response = get_response(request)
  File "/usr/local/lib/python3.5/dist-packages/django/core/handlers/base.py", line 187, in _get_response
    response = self.process_exception_by_middleware(e, request)
  File "/usr/local/lib/python3.5/dist-packages/django/core/handlers/base.py", line 185, in _get_response
    response = wrapped_callback(request, *callback_args, **callback_kwargs)
  File "/root/teach1806/day08/t8/views.py", line 39, in send_my_mail
    msg.send()
  File "/usr/local/lib/python3.5/dist-packages/django/core/mail/message.py", line 348, in send
    return self.get_connection(fail_silently).send_messages([self])
  File "/usr/local/lib/python3.5/dist-packages/django/core/mail/backends/smtp.py", line 104, in send_messages
    new_conn_created = self.open()
  File "/usr/local/lib/python3.5/dist-packages/django/core/mail/backends/smtp.py", line 71, in open
    self.connection.login(force_str(self.username), force_str(self.password))
  File "/usr/lib/python3.5/smtplib.py", line 729, in login
    raise last_exception
  File "/usr/lib/python3.5/smtplib.py", line 720, in login
    initial_response_ok=initial_response_ok)
  File "/usr/lib/python3.5/smtplib.py", line 641, in auth
    raise SMTPAuthenticationError(code, resp)
smtplib.SMTPAuthenticationError: (535, b'Error: \xc7\xeb\xca\xb9\xd3\xc3\xca\xda\xc8\xa8\xc2\xeb\xb5\xc7\xc2\xbc\xa1\xa3\xcf\xea\xc7\xe9\xc7\xeb\xbf\xb4: http://service.mail.qq.com/cgi-bin/help?subtype=1&&id=28&&no=1001256')
2018-06-28 21:34:32,687 [Thread-2:140082188146432] [django.server:124] [basehttp:log_message] [ERROR]- "GET /email HTTP/1.1" 500 97396
2018-06-28 21:34:33,672 [Thread-3:140082188146432] [django.request:135] [exception:handle_uncaught_exception] [ERROR]- Internal Server Error: /email
Traceback (most recent call last):
  File "/usr/local/lib/python3.5/dist-packages/django/core/handlers/exception.py", line 41, in inner
    response = get_response(request)
  File "/usr/local/lib/python3.5/dist-packages/django/core/handlers/base.py", line 187, in _get_response
    response = self.process_exception_by_middleware(e, request)
  File "/usr/local/lib/python3.5/dist-packages/django/core/handlers/base.py", line 185, in _get_response
    response = wrapped_callback(request, *callback_args, **callback_kwargs)
  File "/root/teach1806/day08/t8/views.py", line 39, in send_my_mail
    msg.send()
  File "/usr/local/lib/python3.5/dist-packages/django/core/mail/message.py", line 348, in send
    return self.get_connection(fail_silently).send_messages([self])
  File "/usr/local/lib/python3.5/dist-packages/django/core/mail/backends/smtp.py", line 104, in send_messages
    new_conn_created = self.open()
  File "/usr/local/lib/python3.5/dist-packages/django/core/mail/backends/smtp.py", line 71, in open
    self.connection.login(force_str(self.username), force_str(self.password))
  File "/usr/lib/python3.5/smtplib.py", line 729, in login
    raise last_exception
  File "/usr/lib/python3.5/smtplib.py", line 720, in login
    initial_response_ok=initial_response_ok)
  File "/usr/lib/python3.5/smtplib.py", line 641, in auth
    raise SMTPAuthenticationError(code, resp)
smtplib.SMTPAuthenticationError: (535, b'Error: \xc7\xeb\xca\xb9\xd3\xc3\xca\xda\xc8\xa8\xc2\xeb\xb5\xc7\xc2\xbc\xa1\xa3\xcf\xea\xc7\xe9\xc7\xeb\xbf\xb4: http://service.mail.qq.com/cgi-bin/help?subtype=1&&id=28&&no=1001256')
2018-06-28 21:34:33,672 [Thread-3:140082188146432] [django.request:135] [exception:handle_uncaught_exception] [ERROR]- Internal Server Error: /email
Traceback (most recent call last):
  File "/usr/local/lib/python3.5/dist-packages/django/core/handlers/exception.py", line 41, in inner
    response = get_response(request)
  File "/usr/local/lib/python3.5/dist-packages/django/core/handlers/base.py", line 187, in _get_response
    response = self.process_exception_by_middleware(e, request)
  File "/usr/local/lib/python3.5/dist-packages/django/core/handlers/base.py", line 185, in _get_response
    response = wrapped_callback(request, *callback_args, **callback_kwargs)
  File "/root/teach1806/day08/t8/views.py", line 39, in send_my_mail
    msg.send()
  File "/usr/local/lib/python3.5/dist-packages/django/core/mail/message.py", line 348, in send
    return self.get_connection(fail_silently).send_messages([self])
  File "/usr/local/lib/python3.5/dist-packages/django/core/mail/backends/smtp.py", line 104, in send_messages
    new_conn_created = self.open()
  File "/usr/local/lib/python3.5/dist-packages/django/core/mail/backends/smtp.py", line 71, in open
    self.connection.login(force_str(self.username), force_str(self.password))
  File "/usr/lib/python3.5/smtplib.py", line 729, in login
    raise last_exception
  File "/usr/lib/python3.5/smtplib.py", line 720, in login
    initial_response_ok=initial_response_ok)
  File "/usr/lib/python3.5/smtplib.py", line 641, in auth
    raise SMTPAuthenticationError(code, resp)
smtplib.SMTPAuthenticationError: (535, b'Error: \xc7\xeb\xca\xb9\xd3\xc3\xca\xda\xc8\xa8\xc2\xeb\xb5\xc7\xc2\xbc\xa1\xa3\xcf\xea\xc7\xe9\xc7\xeb\xbf\xb4: http://service.mail.qq.com/cgi-bin/help?subtype=1&&id=28&&no=1001256')
2018-06-28 21:34:33,720 [Thread-3:140082188146432] [django.server:124] [basehttp:log_message] [ERROR]- "GET /email HTTP/1.1" 500 97396
2018-06-28 21:35:03,162 [Dummy-1:139816002991872] [django.db.backends:91] [utils:execute] [DEBUG]- (0.002) SELECT @@SQL_AUTO_IS_NULL; args=None
2018-06-28 21:35:03,165 [Dummy-1:139816002991872] [django.db.backends:91] [utils:execute] [DEBUG]- (0.002) SELECT VERSION(); args=None
2018-06-28 21:35:03,199 [Dummy-1:139816002991872] [django.db.backends:91] [utils:execute] [DEBUG]- (0.003) SHOW FULL TABLES; args=None
2018-06-28 21:35:03,221 [Dummy-1:139816002991872] [django.db.backends:91] [utils:execute] [DEBUG]- (0.003) SELECT `django_migrations`.`app`, `django_migrations`.`name` FROM `django_migrations`; args=()
2018-06-28 21:37:17,691 [Dummy-1:140169140131584] [django.db.backends:91] [utils:execute] [DEBUG]- (0.003) SELECT @@SQL_AUTO_IS_NULL; args=None
2018-06-28 21:37:17,694 [Dummy-1:140169140131584] [django.db.backends:91] [utils:execute] [DEBUG]- (0.003) SELECT VERSION(); args=None
2018-06-28 21:37:17,727 [Dummy-1:140169140131584] [django.db.backends:91] [utils:execute] [DEBUG]- (0.003) SHOW FULL TABLES; args=None
2018-06-28 21:37:17,748 [Dummy-1:140169140131584] [django.db.backends:91] [utils:execute] [DEBUG]- (0.003) SELECT `django_migrations`.`app`, `django_migrations`.`name` FROM `django_migrations`; args=()
2018-06-28 21:38:05,466 [Dummy-1:140368600205056] [django.db.backends:91] [utils:execute] [DEBUG]- (0.002) SELECT @@SQL_AUTO_IS_NULL; args=None
2018-06-28 21:38:05,468 [Dummy-1:140368600205056] [django.db.backends:91] [utils:execute] [DEBUG]- (0.002) SELECT VERSION(); args=None
2018-06-28 21:38:05,505 [Dummy-1:140368600205056] [django.db.backends:91] [utils:execute] [DEBUG]- (0.003) SHOW FULL TABLES; args=None
2018-06-28 21:38:05,527 [Dummy-1:140368600205056] [django.db.backends:91] [utils:execute] [DEBUG]- (0.003) SELECT `django_migrations`.`app`, `django_migrations`.`name` FROM `django_migrations`; args=()
2018-06-28 21:38:08,540 [Thread-2:140368521385728] [django.request:135] [exception:handle_uncaught_exception] [ERROR]- Internal Server Error: /email
Traceback (most recent call last):
  File "/usr/local/lib/python3.5/dist-packages/django/core/handlers/exception.py", line 41, in inner
    response = get_response(request)
  File "/usr/local/lib/python3.5/dist-packages/django/core/handlers/base.py", line 187, in _get_response
    response = self.process_exception_by_middleware(e, request)
  File "/usr/local/lib/python3.5/dist-packages/django/core/handlers/base.py", line 185, in _get_response
    response = wrapped_callback(request, *callback_args, **callback_kwargs)
  File "/root/teach1806/day08/t8/views.py", line 11, in send_my_mail
    send_mail(title,message,email_from,recs)
  File "/usr/local/lib/python3.5/dist-packages/django/core/mail/__init__.py", line 62, in send_mail
    return mail.send()
  File "/usr/local/lib/python3.5/dist-packages/django/core/mail/message.py", line 348, in send
    return self.get_connection(fail_silently).send_messages([self])
  File "/usr/local/lib/python3.5/dist-packages/django/core/mail/backends/smtp.py", line 104, in send_messages
    new_conn_created = self.open()
  File "/usr/local/lib/python3.5/dist-packages/django/core/mail/backends/smtp.py", line 71, in open
    self.connection.login(force_str(self.username), force_str(self.password))
  File "/usr/lib/python3.5/smtplib.py", line 729, in login
    raise last_exception
  File "/usr/lib/python3.5/smtplib.py", line 720, in login
    initial_response_ok=initial_response_ok)
  File "/usr/lib/python3.5/smtplib.py", line 641, in auth
    raise SMTPAuthenticationError(code, resp)
smtplib.SMTPAuthenticationError: (535, b'Error: \xc7\xeb\xca\xb9\xd3\xc3\xca\xda\xc8\xa8\xc2\xeb\xb5\xc7\xc2\xbc\xa1\xa3\xcf\xea\xc7\xe9\xc7\xeb\xbf\xb4: http://service.mail.qq.com/cgi-bin/help?subtype=1&&id=28&&no=1001256')
2018-06-28 21:38:08,540 [Thread-2:140368521385728] [django.request:135] [exception:handle_uncaught_exception] [ERROR]- Internal Server Error: /email
Traceback (most recent call last):
  File "/usr/local/lib/python3.5/dist-packages/django/core/handlers/exception.py", line 41, in inner
    response = get_response(request)
  File "/usr/local/lib/python3.5/dist-packages/django/core/handlers/base.py", line 187, in _get_response
    response = self.process_exception_by_middleware(e, request)
  File "/usr/local/lib/python3.5/dist-packages/django/core/handlers/base.py", line 185, in _get_response
    response = wrapped_callback(request, *callback_args, **callback_kwargs)
  File "/root/teach1806/day08/t8/views.py", line 11, in send_my_mail
    send_mail(title,message,email_from,recs)
  File "/usr/local/lib/python3.5/dist-packages/django/core/mail/__init__.py", line 62, in send_mail
    return mail.send()
  File "/usr/local/lib/python3.5/dist-packages/django/core/mail/message.py", line 348, in send
    return self.get_connection(fail_silently).send_messages([self])
  File "/usr/local/lib/python3.5/dist-packages/django/core/mail/backends/smtp.py", line 104, in send_messages
    new_conn_created = self.open()
  File "/usr/local/lib/python3.5/dist-packages/django/core/mail/backends/smtp.py", line 71, in open
    self.connection.login(force_str(self.username), force_str(self.password))
  File "/usr/lib/python3.5/smtplib.py", line 729, in login
    raise last_exception
  File "/usr/lib/python3.5/smtplib.py", line 720, in login
    initial_response_ok=initial_response_ok)
  File "/usr/lib/python3.5/smtplib.py", line 641, in auth
    raise SMTPAuthenticationError(code, resp)
smtplib.SMTPAuthenticationError: (535, b'Error: \xc7\xeb\xca\xb9\xd3\xc3\xca\xda\xc8\xa8\xc2\xeb\xb5\xc7\xc2\xbc\xa1\xa3\xcf\xea\xc7\xe9\xc7\xeb\xbf\xb4: http://service.mail.qq.com/cgi-bin/help?subtype=1&&id=28&&no=1001256')
2018-06-28 21:38:08,605 [Thread-2:140368521385728] [django.server:124] [basehttp:log_message] [ERROR]- "GET /email HTTP/1.1" 500 102156
2018-06-28 21:38:09,974 [Thread-3:140368521385728] [django.request:135] [exception:handle_uncaught_exception] [ERROR]- Internal Server Error: /email
Traceback (most recent call last):
  File "/usr/local/lib/python3.5/dist-packages/django/core/handlers/exception.py", line 41, in inner
    response = get_response(request)
  File "/usr/local/lib/python3.5/dist-packages/django/core/handlers/base.py", line 187, in _get_response
    response = self.process_exception_by_middleware(e, request)
  File "/usr/local/lib/python3.5/dist-packages/django/core/handlers/base.py", line 185, in _get_response
    response = wrapped_callback(request, *callback_args, **callback_kwargs)
  File "/root/teach1806/day08/t8/views.py", line 11, in send_my_mail
    send_mail(title,message,email_from,recs)
  File "/usr/local/lib/python3.5/dist-packages/django/core/mail/__init__.py", line 62, in send_mail
    return mail.send()
  File "/usr/local/lib/python3.5/dist-packages/django/core/mail/message.py", line 348, in send
    return self.get_connection(fail_silently).send_messages([self])
  File "/usr/local/lib/python3.5/dist-packages/django/core/mail/backends/smtp.py", line 104, in send_messages
    new_conn_created = self.open()
  File "/usr/local/lib/python3.5/dist-packages/django/core/mail/backends/smtp.py", line 71, in open
    self.connection.login(force_str(self.username), force_str(self.password))
  File "/usr/lib/python3.5/smtplib.py", line 729, in login
    raise last_exception
  File "/usr/lib/python3.5/smtplib.py", line 720, in login
    initial_response_ok=initial_response_ok)
  File "/usr/lib/python3.5/smtplib.py", line 641, in auth
    raise SMTPAuthenticationError(code, resp)
smtplib.SMTPAuthenticationError: (535, b'Error: \xc7\xeb\xca\xb9\xd3\xc3\xca\xda\xc8\xa8\xc2\xeb\xb5\xc7\xc2\xbc\xa1\xa3\xcf\xea\xc7\xe9\xc7\xeb\xbf\xb4: http://service.mail.qq.com/cgi-bin/help?subtype=1&&id=28&&no=1001256')
2018-06-28 21:38:09,974 [Thread-3:140368521385728] [django.request:135] [exception:handle_uncaught_exception] [ERROR]- Internal Server Error: /email
Traceback (most recent call last):
  File "/usr/local/lib/python3.5/dist-packages/django/core/handlers/exception.py", line 41, in inner
    response = get_response(request)
  File "/usr/local/lib/python3.5/dist-packages/django/core/handlers/base.py", line 187, in _get_response
    response = self.process_exception_by_middleware(e, request)
  File "/usr/local/lib/python3.5/dist-packages/django/core/handlers/base.py", line 185, in _get_response
    response = wrapped_callback(request, *callback_args, **callback_kwargs)
  File "/root/teach1806/day08/t8/views.py", line 11, in send_my_mail
    send_mail(title,message,email_from,recs)
  File "/usr/local/lib/python3.5/dist-packages/django/core/mail/__init__.py", line 62, in send_mail
    return mail.send()
  File "/usr/local/lib/python3.5/dist-packages/django/core/mail/message.py", line 348, in send
    return self.get_connection(fail_silently).send_messages([self])
  File "/usr/local/lib/python3.5/dist-packages/django/core/mail/backends/smtp.py", line 104, in send_messages
    new_conn_created = self.open()
  File "/usr/local/lib/python3.5/dist-packages/django/core/mail/backends/smtp.py", line 71, in open
    self.connection.login(force_str(self.username), force_str(self.password))
  File "/usr/lib/python3.5/smtplib.py", line 729, in login
    raise last_exception
  File "/usr/lib/python3.5/smtplib.py", line 720, in login
    initial_response_ok=initial_response_ok)
  File "/usr/lib/python3.5/smtplib.py", line 641, in auth
    raise SMTPAuthenticationError(code, resp)
smtplib.SMTPAuthenticationError: (535, b'Error: \xc7\xeb\xca\xb9\xd3\xc3\xca\xda\xc8\xa8\xc2\xeb\xb5\xc7\xc2\xbc\xa1\xa3\xcf\xea\xc7\xe9\xc7\xeb\xbf\xb4: http://service.mail.qq.com/cgi-bin/help?subtype=1&&id=28&&no=1001256')
2018-06-28 21:38:10,034 [Thread-3:140368521385728] [django.server:124] [basehttp:log_message] [ERROR]- "GET /email HTTP/1.1" 500 102156
2018-06-28 21:40:28,046 [Dummy-1:140202165249792] [django.db.backends:91] [utils:execute] [DEBUG]- (0.003) SELECT @@SQL_AUTO_IS_NULL; args=None
2018-06-28 21:40:28,049 [Dummy-1:140202165249792] [django.db.backends:91] [utils:execute] [DEBUG]- (0.003) SELECT VERSION(); args=None
2018-06-28 21:40:28,081 [Dummy-1:140202165249792] [django.db.backends:91] [utils:execute] [DEBUG]- (0.003) SHOW FULL TABLES; args=None
2018-06-28 21:40:28,103 [Dummy-1:140202165249792] [django.db.backends:91] [utils:execute] [DEBUG]- (0.003) SELECT `django_migrations`.`app`, `django_migrations`.`name` FROM `django_migrations`; args=()
2018-06-28 21:40:30,718 [Thread-2:140202153637632] [django.request:135] [exception:handle_uncaught_exception] [ERROR]- Internal Server Error: /email
Traceback (most recent call last):
  File "/usr/local/lib/python3.5/dist-packages/django/core/handlers/exception.py", line 41, in inner
    response = get_response(request)
  File "/usr/local/lib/python3.5/dist-packages/django/core/handlers/base.py", line 187, in _get_response
    response = self.process_exception_by_middleware(e, request)
  File "/usr/local/lib/python3.5/dist-packages/django/core/handlers/base.py", line 185, in _get_response
    response = wrapped_callback(request, *callback_args, **callback_kwargs)
TypeError: send_my_mail() takes 0 positional arguments but 1 was given
2018-06-28 21:40:30,718 [Thread-2:140202153637632] [django.request:135] [exception:handle_uncaught_exception] [ERROR]- Internal Server Error: /email
Traceback (most recent call last):
  File "/usr/local/lib/python3.5/dist-packages/django/core/handlers/exception.py", line 41, in inner
    response = get_response(request)
  File "/usr/local/lib/python3.5/dist-packages/django/core/handlers/base.py", line 187, in _get_response
    response = self.process_exception_by_middleware(e, request)
  File "/usr/local/lib/python3.5/dist-packages/django/core/handlers/base.py", line 185, in _get_response
    response = wrapped_callback(request, *callback_args, **callback_kwargs)
TypeError: send_my_mail() takes 0 positional arguments but 1 was given
2018-06-28 21:40:30,761 [Thread-2:140202153637632] [django.server:124] [basehttp:log_message] [ERROR]- "GET /email HTTP/1.1" 500 63100
2018-06-28 21:40:41,515 [Dummy-1:139858694162176] [django.db.backends:91] [utils:execute] [DEBUG]- (0.003) SELECT @@SQL_AUTO_IS_NULL; args=None
2018-06-28 21:40:41,518 [Dummy-1:139858694162176] [django.db.backends:91] [utils:execute] [DEBUG]- (0.003) SELECT VERSION(); args=None
2018-06-28 21:40:41,551 [Dummy-1:139858694162176] [django.db.backends:91] [utils:execute] [DEBUG]- (0.003) SHOW FULL TABLES; args=None
2018-06-28 21:40:41,573 [Dummy-1:139858694162176] [django.db.backends:91] [utils:execute] [DEBUG]- (0.003) SELECT `django_migrations`.`app`, `django_migrations`.`name` FROM `django_migrations`; args=()
2018-06-28 21:42:19,724 [Dummy-1:139866848200448] [django.db.backends:91] [utils:execute] [DEBUG]- (0.002) SELECT @@SQL_AUTO_IS_NULL; args=None
2018-06-28 21:42:19,727 [Dummy-1:139866848200448] [django.db.backends:91] [utils:execute] [DEBUG]- (0.003) SELECT VERSION(); args=None
2018-06-28 21:42:19,760 [Dummy-1:139866848200448] [django.db.backends:91] [utils:execute] [DEBUG]- (0.003) SHOW FULL TABLES; args=None
2018-06-28 21:42:19,781 [Dummy-1:139866848200448] [django.db.backends:91] [utils:execute] [DEBUG]- (0.003) SELECT `django_migrations`.`app`, `django_migrations`.`name` FROM `django_migrations`; args=()
2018-06-28 21:42:22,778 [Thread-2:139866836588288] [django.request:135] [exception:handle_uncaught_exception] [ERROR]- Internal Server Error: /email
Traceback (most recent call last):
  File "/usr/local/lib/python3.5/dist-packages/django/core/handlers/exception.py", line 41, in inner
    response = get_response(request)
  File "/usr/local/lib/python3.5/dist-packages/django/core/handlers/base.py", line 187, in _get_response
    response = self.process_exception_by_middleware(e, request)
  File "/usr/local/lib/python3.5/dist-packages/django/core/handlers/base.py", line 185, in _get_response
    response = wrapped_callback(request, *callback_args, **callback_kwargs)
  File "/root/teach1806/day08/t8/views.py", line 11, in send_my_mail
    send_mail(title,message,email_from,recs)
  File "/usr/local/lib/python3.5/dist-packages/django/core/mail/__init__.py", line 62, in send_mail
    return mail.send()
  File "/usr/local/lib/python3.5/dist-packages/django/core/mail/message.py", line 348, in send
    return self.get_connection(fail_silently).send_messages([self])
  File "/usr/local/lib/python3.5/dist-packages/django/core/mail/backends/smtp.py", line 104, in send_messages
    new_conn_created = self.open()
  File "/usr/local/lib/python3.5/dist-packages/django/core/mail/backends/smtp.py", line 71, in open
    self.connection.login(force_str(self.username), force_str(self.password))
  File "/usr/lib/python3.5/smtplib.py", line 729, in login
    raise last_exception
  File "/usr/lib/python3.5/smtplib.py", line 720, in login
    initial_response_ok=initial_response_ok)
  File "/usr/lib/python3.5/smtplib.py", line 641, in auth
    raise SMTPAuthenticationError(code, resp)
smtplib.SMTPAuthenticationError: (535, b'Error: \xc7\xeb\xca\xb9\xd3\xc3\xca\xda\xc8\xa8\xc2\xeb\xb5\xc7\xc2\xbc\xa1\xa3\xcf\xea\xc7\xe9\xc7\xeb\xbf\xb4: http://service.mail.qq.com/cgi-bin/help?subtype=1&&id=28&&no=1001256')
2018-06-28 21:42:22,778 [Thread-2:139866836588288] [django.request:135] [exception:handle_uncaught_exception] [ERROR]- Internal Server Error: /email
Traceback (most recent call last):
  File "/usr/local/lib/python3.5/dist-packages/django/core/handlers/exception.py", line 41, in inner
    response = get_response(request)
  File "/usr/local/lib/python3.5/dist-packages/django/core/handlers/base.py", line 187, in _get_response
    response = self.process_exception_by_middleware(e, request)
  File "/usr/local/lib/python3.5/dist-packages/django/core/handlers/base.py", line 185, in _get_response
    response = wrapped_callback(request, *callback_args, **callback_kwargs)
  File "/root/teach1806/day08/t8/views.py", line 11, in send_my_mail
    send_mail(title,message,email_from,recs)
  File "/usr/local/lib/python3.5/dist-packages/django/core/mail/__init__.py", line 62, in send_mail
    return mail.send()
  File "/usr/local/lib/python3.5/dist-packages/django/core/mail/message.py", line 348, in send
    return self.get_connection(fail_silently).send_messages([self])
  File "/usr/local/lib/python3.5/dist-packages/django/core/mail/backends/smtp.py", line 104, in send_messages
    new_conn_created = self.open()
  File "/usr/local/lib/python3.5/dist-packages/django/core/mail/backends/smtp.py", line 71, in open
    self.connection.login(force_str(self.username), force_str(self.password))
  File "/usr/lib/python3.5/smtplib.py", line 729, in login
    raise last_exception
  File "/usr/lib/python3.5/smtplib.py", line 720, in login
    initial_response_ok=initial_response_ok)
  File "/usr/lib/python3.5/smtplib.py", line 641, in auth
    raise SMTPAuthenticationError(code, resp)
smtplib.SMTPAuthenticationError: (535, b'Error: \xc7\xeb\xca\xb9\xd3\xc3\xca\xda\xc8\xa8\xc2\xeb\xb5\xc7\xc2\xbc\xa1\xa3\xcf\xea\xc7\xe9\xc7\xeb\xbf\xb4: http://service.mail.qq.com/cgi-bin/help?subtype=1&&id=28&&no=1001256')
2018-06-28 21:42:22,850 [Thread-2:139866836588288] [django.server:124] [basehttp:log_message] [ERROR]- "GET /email HTTP/1.1" 500 102156
2018-06-28 21:45:51,173 [Thread-4:139866750842624] [django.request:135] [exception:handle_uncaught_exception] [ERROR]- Internal Server Error: /email
Traceback (most recent call last):
  File "/usr/local/lib/python3.5/dist-packages/django/core/handlers/exception.py", line 41, in inner
    response = get_response(request)
  File "/usr/local/lib/python3.5/dist-packages/django/core/handlers/base.py", line 187, in _get_response
    response = self.process_exception_by_middleware(e, request)
  File "/usr/local/lib/python3.5/dist-packages/django/core/handlers/base.py", line 185, in _get_response
    response = wrapped_callback(request, *callback_args, **callback_kwargs)
  File "/root/teach1806/day08/t8/views.py", line 11, in send_my_mail
    send_mail(title,message,email_from,recs)
  File "/usr/local/lib/python3.5/dist-packages/django/core/mail/__init__.py", line 62, in send_mail
    return mail.send()
  File "/usr/local/lib/python3.5/dist-packages/django/core/mail/message.py", line 348, in send
    return self.get_connection(fail_silently).send_messages([self])
  File "/usr/local/lib/python3.5/dist-packages/django/core/mail/backends/smtp.py", line 104, in send_messages
    new_conn_created = self.open()
  File "/usr/local/lib/python3.5/dist-packages/django/core/mail/backends/smtp.py", line 71, in open
    self.connection.login(force_str(self.username), force_str(self.password))
  File "/usr/lib/python3.5/smtplib.py", line 729, in login
    raise last_exception
  File "/usr/lib/python3.5/smtplib.py", line 720, in login
    initial_response_ok=initial_response_ok)
  File "/usr/lib/python3.5/smtplib.py", line 641, in auth
    raise SMTPAuthenticationError(code, resp)
smtplib.SMTPAuthenticationError: (535, b'Error: \xc7\xeb\xca\xb9\xd3\xc3\xca\xda\xc8\xa8\xc2\xeb\xb5\xc7\xc2\xbc\xa1\xa3\xcf\xea\xc7\xe9\xc7\xeb\xbf\xb4: http://service.mail.qq.com/cgi-bin/help?subtype=1&&id=28&&no=1001256')
2018-06-28 21:45:51,173 [Thread-4:139866750842624] [django.request:135] [exception:handle_uncaught_exception] [ERROR]- Internal Server Error: /email
Traceback (most recent call last):
  File "/usr/local/lib/python3.5/dist-packages/django/core/handlers/exception.py", line 41, in inner
    response = get_response(request)
  File "/usr/local/lib/python3.5/dist-packages/django/core/handlers/base.py", line 187, in _get_response
    response = self.process_exception_by_middleware(e, request)
  File "/usr/local/lib/python3.5/dist-packages/django/core/handlers/base.py", line 185, in _get_response
    response = wrapped_callback(request, *callback_args, **callback_kwargs)
  File "/root/teach1806/day08/t8/views.py", line 11, in send_my_mail
    send_mail(title,message,email_from,recs)
  File "/usr/local/lib/python3.5/dist-packages/django/core/mail/__init__.py", line 62, in send_mail
    return mail.send()
  File "/usr/local/lib/python3.5/dist-packages/django/core/mail/message.py", line 348, in send
    return self.get_connection(fail_silently).send_messages([self])
  File "/usr/local/lib/python3.5/dist-packages/django/core/mail/backends/smtp.py", line 104, in send_messages
    new_conn_created = self.open()
  File "/usr/local/lib/python3.5/dist-packages/django/core/mail/backends/smtp.py", line 71, in open
    self.connection.login(force_str(self.username), force_str(self.password))
  File "/usr/lib/python3.5/smtplib.py", line 729, in login
    raise last_exception
  File "/usr/lib/python3.5/smtplib.py", line 720, in login
    initial_response_ok=initial_response_ok)
  File "/usr/lib/python3.5/smtplib.py", line 641, in auth
    raise SMTPAuthenticationError(code, resp)
smtplib.SMTPAuthenticationError: (535, b'Error: \xc7\xeb\xca\xb9\xd3\xc3\xca\xda\xc8\xa8\xc2\xeb\xb5\xc7\xc2\xbc\xa1\xa3\xcf\xea\xc7\xe9\xc7\xeb\xbf\xb4: http://service.mail.qq.com/cgi-bin/help?subtype=1&&id=28&&no=1001256')
2018-06-28 21:45:51,223 [Thread-4:139866750842624] [django.server:124] [basehttp:log_message] [ERROR]- "GET /email HTTP/1.1" 500 102156
2018-06-28 21:45:52,450 [Thread-3:139866836588288] [django.request:135] [exception:handle_uncaught_exception] [ERROR]- Internal Server Error: /email
Traceback (most recent call last):
  File "/usr/local/lib/python3.5/dist-packages/django/core/handlers/exception.py", line 41, in inner
    response = get_response(request)
  File "/usr/local/lib/python3.5/dist-packages/django/core/handlers/base.py", line 187, in _get_response
    response = self.process_exception_by_middleware(e, request)
  File "/usr/local/lib/python3.5/dist-packages/django/core/handlers/base.py", line 185, in _get_response
    response = wrapped_callback(request, *callback_args, **callback_kwargs)
  File "/root/teach1806/day08/t8/views.py", line 11, in send_my_mail
    send_mail(title,message,email_from,recs)
  File "/usr/local/lib/python3.5/dist-packages/django/core/mail/__init__.py", line 62, in send_mail
    return mail.send()
  File "/usr/local/lib/python3.5/dist-packages/django/core/mail/message.py", line 348, in send
    return self.get_connection(fail_silently).send_messages([self])
  File "/usr/local/lib/python3.5/dist-packages/django/core/mail/backends/smtp.py", line 104, in send_messages
    new_conn_created = self.open()
  File "/usr/local/lib/python3.5/dist-packages/django/core/mail/backends/smtp.py", line 71, in open
    self.connection.login(force_str(self.username), force_str(self.password))
  File "/usr/lib/python3.5/smtplib.py", line 729, in login
    raise last_exception
  File "/usr/lib/python3.5/smtplib.py", line 720, in login
    initial_response_ok=initial_response_ok)
  File "/usr/lib/python3.5/smtplib.py", line 641, in auth
    raise SMTPAuthenticationError(code, resp)
smtplib.SMTPAuthenticationError: (535, b'Error: \xc7\xeb\xca\xb9\xd3\xc3\xca\xda\xc8\xa8\xc2\xeb\xb5\xc7\xc2\xbc\xa1\xa3\xcf\xea\xc7\xe9\xc7\xeb\xbf\xb4: http://service.mail.qq.com/cgi-bin/help?subtype=1&&id=28&&no=1001256')
2018-06-28 21:45:52,450 [Thread-3:139866836588288] [django.request:135] [exception:handle_uncaught_exception] [ERROR]- Internal Server Error: /email
Traceback (most recent call last):
  File "/usr/local/lib/python3.5/dist-packages/django/core/handlers/exception.py", line 41, in inner
    response = get_response(request)
  File "/usr/local/lib/python3.5/dist-packages/django/core/handlers/base.py", line 187, in _get_response
    response = self.process_exception_by_middleware(e, request)
  File "/usr/local/lib/python3.5/dist-packages/django/core/handlers/base.py", line 185, in _get_response
    response = wrapped_callback(request, *callback_args, **callback_kwargs)
  File "/root/teach1806/day08/t8/views.py", line 11, in send_my_mail
    send_mail(title,message,email_from,recs)
  File "/usr/local/lib/python3.5/dist-packages/django/core/mail/__init__.py", line 62, in send_mail
    return mail.send()
  File "/usr/local/lib/python3.5/dist-packages/django/core/mail/message.py", line 348, in send
    return self.get_connection(fail_silently).send_messages([self])
  File "/usr/local/lib/python3.5/dist-packages/django/core/mail/backends/smtp.py", line 104, in send_messages
    new_conn_created = self.open()
  File "/usr/local/lib/python3.5/dist-packages/django/core/mail/backends/smtp.py", line 71, in open
    self.connection.login(force_str(self.username), force_str(self.password))
  File "/usr/lib/python3.5/smtplib.py", line 729, in login
    raise last_exception
  File "/usr/lib/python3.5/smtplib.py", line 720, in login
    initial_response_ok=initial_response_ok)
  File "/usr/lib/python3.5/smtplib.py", line 641, in auth
    raise SMTPAuthenticationError(code, resp)
smtplib.SMTPAuthenticationError: (535, b'Error: \xc7\xeb\xca\xb9\xd3\xc3\xca\xda\xc8\xa8\xc2\xeb\xb5\xc7\xc2\xbc\xa1\xa3\xcf\xea\xc7\xe9\xc7\xeb\xbf\xb4: http://service.mail.qq.com/cgi-bin/help?subtype=1&&id=28&&no=1001256')
2018-06-28 21:45:52,515 [Thread-3:139866836588288] [django.server:124] [basehttp:log_message] [ERROR]- "GET /email HTTP/1.1" 500 102156
2018-06-28 21:53:21,397 [Dummy-1:140298163230464] [django.db.backends:91] [utils:execute] [DEBUG]- (0.003) SELECT @@SQL_AUTO_IS_NULL; args=None
2018-06-28 21:53:21,400 [Dummy-1:140298163230464] [django.db.backends:91] [utils:execute] [DEBUG]- (0.003) SELECT VERSION(); args=None
2018-06-28 21:53:21,432 [Dummy-1:140298163230464] [django.db.backends:91] [utils:execute] [DEBUG]- (0.003) SHOW FULL TABLES; args=None
2018-06-28 21:53:21,453 [Dummy-1:140298163230464] [django.db.backends:91] [utils:execute] [DEBUG]- (0.003) SELECT `django_migrations`.`app`, `django_migrations`.`name` FROM `django_migrations`; args=()
2018-06-28 21:53:27,468 [Thread-2:140298151618304] [django.server:124] [basehttp:log_message] [INFO]- "GET /email HTTP/1.1" 200 21
2018-06-28 21:58:14,105 [Dummy-1:140306626463488] [django.db.backends:91] [utils:execute] [DEBUG]- (0.002) SELECT @@SQL_AUTO_IS_NULL; args=None
2018-06-28 21:58:14,108 [Dummy-1:140306626463488] [django.db.backends:91] [utils:execute] [DEBUG]- (0.002) SELECT VERSION(); args=None
2018-06-28 21:58:14,141 [Dummy-1:140306626463488] [django.db.backends:91] [utils:execute] [DEBUG]- (0.003) SHOW FULL TABLES; args=None
2018-06-28 21:58:14,161 [Dummy-1:140306626463488] [django.db.backends:91] [utils:execute] [DEBUG]- (0.003) SELECT `django_migrations`.`app`, `django_migrations`.`name` FROM `django_migrations`; args=()
2018-06-28 21:58:23,374 [Thread-2:140306614851328] [django.server:124] [basehttp:log_message] [INFO]- "GET /email HTTP/1.1" 200 21
2018-06-28 21:58:45,725 [Thread-4:140306606458624] [django.server:124] [basehttp:log_message] [INFO]- "GET /email HTTP/1.1" 200 21
2018-06-28 22:00:58,475 [Dummy-1:140628165154560] [django.db.backends:91] [utils:execute] [DEBUG]- (0.002) SELECT @@SQL_AUTO_IS_NULL; args=None
2018-06-28 22:00:58,477 [Dummy-1:140628165154560] [django.db.backends:91] [utils:execute] [DEBUG]- (0.002) SELECT VERSION(); args=None
2018-06-28 22:00:58,511 [Dummy-1:140628165154560] [django.db.backends:91] [utils:execute] [DEBUG]- (0.002) SHOW FULL TABLES; args=None
2018-06-28 22:00:58,530 [Dummy-1:140628165154560] [django.db.backends:91] [utils:execute] [DEBUG]- (0.002) SELECT `django_migrations`.`app`, `django_migrations`.`name` FROM `django_migrations`; args=()
2018-06-28 22:01:08,205 [Dummy-1:140712677521152] [django.db.backends:91] [utils:execute] [DEBUG]- (0.002) SELECT @@SQL_AUTO_IS_NULL; args=None
2018-06-28 22:01:08,208 [Dummy-1:140712677521152] [django.db.backends:91] [utils:execute] [DEBUG]- (0.002) SELECT VERSION(); args=None
2018-06-28 22:01:08,241 [Dummy-1:140712677521152] [django.db.backends:91] [utils:execute] [DEBUG]- (0.003) SHOW FULL TABLES; args=None
2018-06-28 22:01:08,260 [Dummy-1:140712677521152] [django.db.backends:91] [utils:execute] [DEBUG]- (0.003) SELECT `django_migrations`.`app`, `django_migrations`.`name` FROM `django_migrations`; args=()
2018-06-28 22:01:17,739 [Thread-2:140712590964480] [django.template:925] [base:_resolve_lookup] [DEBUG]- Exception while resolving variable 'name' in template 'unknown'.
Traceback (most recent call last):
  File "/usr/local/lib/python3.5/dist-packages/django/core/handlers/exception.py", line 41, in inner
    response = get_response(request)
  File "/usr/local/lib/python3.5/dist-packages/django/core/handlers/base.py", line 172, in _get_response
    resolver_match = resolver.resolve(request.path_info)
  File "/usr/local/lib/python3.5/dist-packages/django/urls/resolvers.py", line 392, in resolve
    raise Resolver404({'tried': tried, 'path': new_path})
django.urls.exceptions.Resolver404: {'tried': [[<RegexURLResolver <RegexURLPattern list> (admin:admin) ^admin/>], [<RegexURLPattern None ^email$>]], 'path': ''}

During handling of the above exception, another exception occurred:

Traceback (most recent call last):
  File "/usr/local/lib/python3.5/dist-packages/django/template/base.py", line 882, in _resolve_lookup
    current = current[bit]
TypeError: 'RegexURLResolver' object is not subscriptable

During handling of the above exception, another exception occurred:

Traceback (most recent call last):
  File "/usr/local/lib/python3.5/dist-packages/django/template/base.py", line 890, in _resolve_lookup
    current = getattr(current, bit)
AttributeError: 'RegexURLResolver' object has no attribute 'name'

During handling of the above exception, another exception occurred:

Traceback (most recent call last):
  File "/usr/local/lib/python3.5/dist-packages/django/template/base.py", line 896, in _resolve_lookup
    current = current[int(bit)]
ValueError: invalid literal for int() with base 10: 'name'

During handling of the above exception, another exception occurred:

Traceback (most recent call last):
  File "/usr/local/lib/python3.5/dist-packages/django/template/base.py", line 903, in _resolve_lookup
    (bit, current))  # missing attribute
django.template.base.VariableDoesNotExist: Failed lookup for key [name] in '<RegexURLResolver <RegexURLPattern list> (admin:admin) ^admin/>'
2018-06-28 22:01:17,741 [Thread-2:140712590964480] [django.server:124] [basehttp:log_message] [WARNING]- "GET / HTTP/1.1" 404 2023
2018-06-28 22:01:40,842 [Dummy-1:139673904490240] [django.db.backends:91] [utils:execute] [DEBUG]- (0.003) SELECT @@SQL_AUTO_IS_NULL; args=None
2018-06-28 22:01:40,846 [Dummy-1:139673904490240] [django.db.backends:91] [utils:execute] [DEBUG]- (0.003) SELECT VERSION(); args=None
2018-06-28 22:01:40,878 [Dummy-1:139673904490240] [django.db.backends:91] [utils:execute] [DEBUG]- (0.003) SHOW FULL TABLES; args=None
2018-06-28 22:01:40,898 [Dummy-1:139673904490240] [django.db.backends:91] [utils:execute] [DEBUG]- (0.003) SELECT `django_migrations`.`app`, `django_migrations`.`name` FROM `django_migrations`; args=()
2018-06-28 22:01:50,364 [Thread-3:139673812858624] [django.server:124] [basehttp:log_message] [INFO]- "GET /email HTTP/1.1" 200 12
2018-06-28 22:06:40,741 [Dummy-1:140393058903808] [django.db.backends:91] [utils:execute] [DEBUG]- (0.002) SELECT @@SQL_AUTO_IS_NULL; args=None
2018-06-28 22:06:40,744 [Dummy-1:140393058903808] [django.db.backends:91] [utils:execute] [DEBUG]- (0.002) SELECT VERSION(); args=None
2018-06-28 22:06:40,775 [Dummy-1:140393058903808] [django.db.backends:91] [utils:execute] [DEBUG]- (0.003) SHOW FULL TABLES; args=None
2018-06-28 22:06:40,794 [Dummy-1:140393058903808] [django.db.backends:91] [utils:execute] [DEBUG]- (0.003) SELECT `django_migrations`.`app`, `django_migrations`.`name` FROM `django_migrations`; args=()
2018-06-28 22:07:03,304 [Dummy-1:140673633642240] [django.db.backends:91] [utils:execute] [DEBUG]- (0.002) SELECT @@SQL_AUTO_IS_NULL; args=None
2018-06-28 22:07:03,307 [Dummy-1:140673633642240] [django.db.backends:91] [utils:execute] [DEBUG]- (0.002) SELECT VERSION(); args=None
2018-06-28 22:07:12,726 [Dummy-1:140602751284992] [django.db.backends:91] [utils:execute] [DEBUG]- (0.002) SELECT @@SQL_AUTO_IS_NULL; args=None
2018-06-28 22:07:12,729 [Dummy-1:140602751284992] [django.db.backends:91] [utils:execute] [DEBUG]- (0.002) SELECT VERSION(); args=None
2018-06-28 22:08:04,505 [Dummy-1:140126177560320] [django.db.backends:91] [utils:execute] [DEBUG]- (0.003) SELECT @@SQL_AUTO_IS_NULL; args=None
2018-06-28 22:08:04,508 [Dummy-1:140126177560320] [django.db.backends:91] [utils:execute] [DEBUG]- (0.003) SELECT VERSION(); args=None
2018-06-28 22:11:22,478 [Dummy-1:140408317298432] [django.db.backends:91] [utils:execute] [DEBUG]- (0.002) SELECT @@SQL_AUTO_IS_NULL; args=None
2018-06-28 22:11:22,481 [Dummy-1:140408317298432] [django.db.backends:91] [utils:execute] [DEBUG]- (0.002) SELECT VERSION(); args=None
2018-06-28 22:11:35,945 [Dummy-1:139875327338240] [django.db.backends:91] [utils:execute] [DEBUG]- (0.002) SELECT @@SQL_AUTO_IS_NULL; args=None
2018-06-28 22:11:35,948 [Dummy-1:139875327338240] [django.db.backends:91] [utils:execute] [DEBUG]- (0.002) SELECT VERSION(); args=None
2018-06-28 22:11:47,394 [Dummy-1:140395308844800] [django.db.backends:91] [utils:execute] [DEBUG]- (0.002) SELECT @@SQL_AUTO_IS_NULL; args=None
2018-06-28 22:11:47,397 [Dummy-1:140395308844800] [django.db.backends:91] [utils:execute] [DEBUG]- (0.002) SELECT VERSION(); args=None
2018-06-28 22:11:56,813 [Dummy-1:139783897675520] [django.db.backends:91] [utils:execute] [DEBUG]- (0.002) SELECT @@SQL_AUTO_IS_NULL; args=None
2018-06-28 22:11:56,816 [Dummy-1:139783897675520] [django.db.backends:91] [utils:execute] [DEBUG]- (0.002) SELECT VERSION(); args=None
2018-06-28 22:11:56,848 [Dummy-1:139783897675520] [django.db.backends:91] [utils:execute] [DEBUG]- (0.003) SHOW FULL TABLES; args=None
2018-06-28 22:11:56,867 [Dummy-1:139783897675520] [django.db.backends:91] [utils:execute] [DEBUG]- (0.003) SELECT `django_migrations`.`app`, `django_migrations`.`name` FROM `django_migrations`; args=()
2018-06-28 22:17:48,094 [Dummy-1:140000943621888] [django.db.backends:91] [utils:execute] [DEBUG]- (0.002) SELECT @@SQL_AUTO_IS_NULL; args=None
2018-06-28 22:17:48,096 [Dummy-1:140000943621888] [django.db.backends:91] [utils:execute] [DEBUG]- (0.002) SELECT VERSION(); args=None
2018-06-28 22:17:48,134 [Dummy-1:140000943621888] [django.db.backends:91] [utils:execute] [DEBUG]- (0.003) SHOW FULL TABLES; args=None
2018-06-28 22:17:48,157 [Dummy-1:140000943621888] [django.db.backends:91] [utils:execute] [DEBUG]- (0.003) SELECT `django_migrations`.`app`, `django_migrations`.`name` FROM `django_migrations`; args=()
2018-06-28 22:21:45,647 [Thread-2:140000932009728] [django.server:124] [basehttp:log_message] [INFO]- "GET /htmlems HTTP/1.1" 200 15
2018-06-28 22:26:07,538 [Dummy-1:140074348328704] [django.db.backends:91] [utils:execute] [DEBUG]- (0.002) SELECT @@SQL_AUTO_IS_NULL; args=None
2018-06-28 22:26:07,541 [Dummy-1:140074348328704] [django.db.backends:91] [utils:execute] [DEBUG]- (0.002) SELECT VERSION(); args=None
2018-06-28 22:26:07,573 [Dummy-1:140074348328704] [django.db.backends:91] [utils:execute] [DEBUG]- (0.003) SHOW FULL TABLES; args=None
2018-06-28 22:26:07,592 [Dummy-1:140074348328704] [django.db.backends:91] [utils:execute] [DEBUG]- (0.003) SELECT `django_migrations`.`app`, `django_migrations`.`name` FROM `django_migrations`; args=()
2018-06-28 22:26:13,406 [Thread-2:140074336716544] [django.server:124] [basehttp:log_message] [INFO]- "GET /htmlems HTTP/1.1" 200 15
2018-06-28 22:27:47,946 [Thread-4:140074328323840] [django.server:124] [basehttp:log_message] [INFO]- "GET /htmlems HTTP/1.1" 200 15
2018-06-28 22:29:50,200 [Dummy-1:140363928934144] [django.db.backends:91] [utils:execute] [DEBUG]- (0.003) SELECT @@SQL_AUTO_IS_NULL; args=None
2018-06-28 22:29:50,203 [Dummy-1:140363928934144] [django.db.backends:91] [utils:execute] [DEBUG]- (0.003) SELECT VERSION(); args=None
2018-06-28 22:29:50,235 [Dummy-1:140363928934144] [django.db.backends:91] [utils:execute] [DEBUG]- (0.002) SHOW FULL TABLES; args=None
2018-06-28 22:29:50,257 [Dummy-1:140363928934144] [django.db.backends:91] [utils:execute] [DEBUG]- (0.003) SELECT `django_migrations`.`app`, `django_migrations`.`name` FROM `django_migrations`; args=()
2018-06-28 22:29:56,209 [Thread-3:140363908929280] [django.request:135] [exception:handle_uncaught_exception] [ERROR]- Internal Server Error: /htmlems
Traceback (most recent call last):
  File "/usr/local/lib/python3.5/dist-packages/django/core/handlers/exception.py", line 41, in inner
    response = get_response(request)
  File "/usr/local/lib/python3.5/dist-packages/django/core/handlers/base.py", line 187, in _get_response
    response = self.process_exception_by_middleware(e, request)
  File "/usr/local/lib/python3.5/dist-packages/django/core/handlers/base.py", line 185, in _get_response
    response = wrapped_callback(request, *callback_args, **callback_kwargs)
  File "/root/teach1806/day08/t8/views.py", line 11, in send_my_mail
    send_mail(title,message,email_from,recs)
  File "/usr/local/lib/python3.5/dist-packages/django/core/mail/__init__.py", line 62, in send_mail
    return mail.send()
  File "/usr/local/lib/python3.5/dist-packages/django/core/mail/message.py", line 348, in send
    return self.get_connection(fail_silently).send_messages([self])
  File "/usr/local/lib/python3.5/dist-packages/django/core/mail/backends/smtp.py", line 111, in send_messages
    sent = self._send(message)
  File "/usr/local/lib/python3.5/dist-packages/django/core/mail/backends/smtp.py", line 127, in _send
    self.connection.sendmail(from_email, recipients, message.as_bytes(linesep='\r\n'))
  File "/usr/lib/python3.5/smtplib.py", line 862, in sendmail
    raise SMTPSenderRefused(code, resp, from_addr)
smtplib.SMTPSenderRefused: (503, b'Error: need EHLO and AUTH first !', '3369571193@qq.com')
2018-06-28 22:29:56,209 [Thread-3:140363908929280] [django.request:135] [exception:handle_uncaught_exception] [ERROR]- Internal Server Error: /htmlems
Traceback (most recent call last):
  File "/usr/local/lib/python3.5/dist-packages/django/core/handlers/exception.py", line 41, in inner
    response = get_response(request)
  File "/usr/local/lib/python3.5/dist-packages/django/core/handlers/base.py", line 187, in _get_response
    response = self.process_exception_by_middleware(e, request)
  File "/usr/local/lib/python3.5/dist-packages/django/core/handlers/base.py", line 185, in _get_response
    response = wrapped_callback(request, *callback_args, **callback_kwargs)
  File "/root/teach1806/day08/t8/views.py", line 11, in send_my_mail
    send_mail(title,message,email_from,recs)
  File "/usr/local/lib/python3.5/dist-packages/django/core/mail/__init__.py", line 62, in send_mail
    return mail.send()
  File "/usr/local/lib/python3.5/dist-packages/django/core/mail/message.py", line 348, in send
    return self.get_connection(fail_silently).send_messages([self])
  File "/usr/local/lib/python3.5/dist-packages/django/core/mail/backends/smtp.py", line 111, in send_messages
    sent = self._send(message)
  File "/usr/local/lib/python3.5/dist-packages/django/core/mail/backends/smtp.py", line 127, in _send
    self.connection.sendmail(from_email, recipients, message.as_bytes(linesep='\r\n'))
  File "/usr/lib/python3.5/smtplib.py", line 862, in sendmail
    raise SMTPSenderRefused(code, resp, from_addr)
smtplib.SMTPSenderRefused: (503, b'Error: need EHLO and AUTH first !', '3369571193@qq.com')
2018-06-28 22:29:56,281 [Thread-3:140363908929280] [django.server:124] [basehttp:log_message] [ERROR]- "GET /htmlems HTTP/1.1" 500 91878
2018-06-28 22:30:00,159 [Thread-2:140363917321984] [django.request:135] [exception:handle_uncaught_exception] [ERROR]- Internal Server Error: /htmlems
Traceback (most recent call last):
  File "/usr/local/lib/python3.5/dist-packages/django/core/handlers/exception.py", line 41, in inner
    response = get_response(request)
  File "/usr/local/lib/python3.5/dist-packages/django/core/handlers/base.py", line 187, in _get_response
    response = self.process_exception_by_middleware(e, request)
  File "/usr/local/lib/python3.5/dist-packages/django/core/handlers/base.py", line 185, in _get_response
    response = wrapped_callback(request, *callback_args, **callback_kwargs)
  File "/root/teach1806/day08/t8/views.py", line 11, in send_my_mail
    send_mail(title,message,email_from,recs)
  File "/usr/local/lib/python3.5/dist-packages/django/core/mail/__init__.py", line 62, in send_mail
    return mail.send()
  File "/usr/local/lib/python3.5/dist-packages/django/core/mail/message.py", line 348, in send
    return self.get_connection(fail_silently).send_messages([self])
  File "/usr/local/lib/python3.5/dist-packages/django/core/mail/backends/smtp.py", line 111, in send_messages
    sent = self._send(message)
  File "/usr/local/lib/python3.5/dist-packages/django/core/mail/backends/smtp.py", line 127, in _send
    self.connection.sendmail(from_email, recipients, message.as_bytes(linesep='\r\n'))
  File "/usr/lib/python3.5/smtplib.py", line 862, in sendmail
    raise SMTPSenderRefused(code, resp, from_addr)
smtplib.SMTPSenderRefused: (503, b'Error: need EHLO and AUTH first !', '3369571193@qq.com')
2018-06-28 22:30:00,159 [Thread-2:140363917321984] [django.request:135] [exception:handle_uncaught_exception] [ERROR]- Internal Server Error: /htmlems
Traceback (most recent call last):
  File "/usr/local/lib/python3.5/dist-packages/django/core/handlers/exception.py", line 41, in inner
    response = get_response(request)
  File "/usr/local/lib/python3.5/dist-packages/django/core/handlers/base.py", line 187, in _get_response
    response = self.process_exception_by_middleware(e, request)
  File "/usr/local/lib/python3.5/dist-packages/django/core/handlers/base.py", line 185, in _get_response
    response = wrapped_callback(request, *callback_args, **callback_kwargs)
  File "/root/teach1806/day08/t8/views.py", line 11, in send_my_mail
    send_mail(title,message,email_from,recs)
  File "/usr/local/lib/python3.5/dist-packages/django/core/mail/__init__.py", line 62, in send_mail
    return mail.send()
  File "/usr/local/lib/python3.5/dist-packages/django/core/mail/message.py", line 348, in send
    return self.get_connection(fail_silently).send_messages([self])
  File "/usr/local/lib/python3.5/dist-packages/django/core/mail/backends/smtp.py", line 111, in send_messages
    sent = self._send(message)
  File "/usr/local/lib/python3.5/dist-packages/django/core/mail/backends/smtp.py", line 127, in _send
    self.connection.sendmail(from_email, recipients, message.as_bytes(linesep='\r\n'))
  File "/usr/lib/python3.5/smtplib.py", line 862, in sendmail
    raise SMTPSenderRefused(code, resp, from_addr)
smtplib.SMTPSenderRefused: (503, b'Error: need EHLO and AUTH first !', '3369571193@qq.com')
2018-06-28 22:30:00,220 [Thread-2:140363917321984] [django.server:124] [basehttp:log_message] [ERROR]- "GET /htmlems HTTP/1.1" 500 91752
2018-06-28 22:30:02,390 [Thread-5:140363917321984] [django.template:925] [base:_resolve_lookup] [DEBUG]- Exception while resolving variable 'name' in template 'unknown'.
Traceback (most recent call last):
  File "/usr/local/lib/python3.5/dist-packages/django/core/handlers/exception.py", line 41, in inner
    response = get_response(request)
  File "/usr/local/lib/python3.5/dist-packages/django/core/handlers/base.py", line 172, in _get_response
    resolver_match = resolver.resolve(request.path_info)
  File "/usr/local/lib/python3.5/dist-packages/django/urls/resolvers.py", line 392, in resolve
    raise Resolver404({'tried': tried, 'path': new_path})
django.urls.exceptions.Resolver404: {'path': 'email_from', 'tried': [[<RegexURLResolver <RegexURLPattern list> (admin:admin) ^admin/>], [<RegexURLPattern None ^email$>], [<RegexURLPattern None ^ems$>], [<RegexURLPattern None ^htmlems$>], [<RegexURLPattern None ^text$>], [<RegexURLPattern None ^verify/(.+)>]]}

During handling of the above exception, another exception occurred:

Traceback (most recent call last):
  File "/usr/local/lib/python3.5/dist-packages/django/template/base.py", line 882, in _resolve_lookup
    current = current[bit]
TypeError: 'RegexURLResolver' object is not subscriptable

During handling of the above exception, another exception occurred:

Traceback (most recent call last):
  File "/usr/local/lib/python3.5/dist-packages/django/template/base.py", line 890, in _resolve_lookup
    current = getattr(current, bit)
AttributeError: 'RegexURLResolver' object has no attribute 'name'

During handling of the above exception, another exception occurred:

Traceback (most recent call last):
  File "/usr/local/lib/python3.5/dist-packages/django/template/base.py", line 896, in _resolve_lookup
    current = current[int(bit)]
ValueError: invalid literal for int() with base 10: 'name'

During handling of the above exception, another exception occurred:

Traceback (most recent call last):
  File "/usr/local/lib/python3.5/dist-packages/django/template/base.py", line 903, in _resolve_lookup
    (bit, current))  # missing attribute
django.template.base.VariableDoesNotExist: Failed lookup for key [name] in '<RegexURLResolver <RegexURLPattern list> (admin:admin) ^admin/>'
2018-06-28 22:30:02,393 [Thread-5:140363917321984] [django.server:124] [basehttp:log_message] [WARNING]- "GET /email_from HTTP/1.1" 404 2497
2018-06-28 22:30:25,702 [Thread-6:140363917321984] [django.template:925] [base:_resolve_lookup] [DEBUG]- Exception while resolving variable 'name' in template 'unknown'.
Traceback (most recent call last):
  File "/usr/local/lib/python3.5/dist-packages/django/core/handlers/exception.py", line 41, in inner
    response = get_response(request)
  File "/usr/local/lib/python3.5/dist-packages/django/core/handlers/base.py", line 172, in _get_response
    resolver_match = resolver.resolve(request.path_info)
  File "/usr/local/lib/python3.5/dist-packages/django/urls/resolvers.py", line 392, in resolve
    raise Resolver404({'tried': tried, 'path': new_path})
django.urls.exceptions.Resolver404: {'path': 'email_from', 'tried': [[<RegexURLResolver <RegexURLPattern list> (admin:admin) ^admin/>], [<RegexURLPattern None ^email$>], [<RegexURLPattern None ^ems$>], [<RegexURLPattern None ^htmlems$>], [<RegexURLPattern None ^text$>], [<RegexURLPattern None ^verify/(.+)>]]}

During handling of the above exception, another exception occurred:

Traceback (most recent call last):
  File "/usr/local/lib/python3.5/dist-packages/django/template/base.py", line 882, in _resolve_lookup
    current = current[bit]
TypeError: 'RegexURLResolver' object is not subscriptable

During handling of the above exception, another exception occurred:

Traceback (most recent call last):
  File "/usr/local/lib/python3.5/dist-packages/django/template/base.py", line 890, in _resolve_lookup
    current = getattr(current, bit)
AttributeError: 'RegexURLResolver' object has no attribute 'name'

During handling of the above exception, another exception occurred:

Traceback (most recent call last):
  File "/usr/local/lib/python3.5/dist-packages/django/template/base.py", line 896, in _resolve_lookup
    current = current[int(bit)]
ValueError: invalid literal for int() with base 10: 'name'

During handling of the above exception, another exception occurred:

Traceback (most recent call last):
  File "/usr/local/lib/python3.5/dist-packages/django/template/base.py", line 903, in _resolve_lookup
    (bit, current))  # missing attribute
django.template.base.VariableDoesNotExist: Failed lookup for key [name] in '<RegexURLResolver <RegexURLPattern list> (admin:admin) ^admin/>'
2018-06-28 22:30:25,704 [Thread-6:140363917321984] [django.server:124] [basehttp:log_message] [WARNING]- "GET /email_from HTTP/1.1" 404 2503
2018-06-28 22:30:29,906 [Dummy-1:140436426880768] [django.db.backends:91] [utils:execute] [DEBUG]- (0.002) SELECT @@SQL_AUTO_IS_NULL; args=None
2018-06-28 22:30:29,909 [Dummy-1:140436426880768] [django.db.backends:91] [utils:execute] [DEBUG]- (0.002) SELECT VERSION(); args=None
2018-06-28 22:30:29,940 [Dummy-1:140436426880768] [django.db.backends:91] [utils:execute] [DEBUG]- (0.002) SHOW FULL TABLES; args=None
2018-06-28 22:30:29,959 [Dummy-1:140436426880768] [django.db.backends:91] [utils:execute] [DEBUG]- (0.002) SELECT `django_migrations`.`app`, `django_migrations`.`name` FROM `django_migrations`; args=()
2018-06-28 22:30:33,563 [Thread-2:140436415268608] [django.server:124] [basehttp:log_message] [INFO]- "GET /htmlems HTTP/1.1" 200 15
2018-06-28 22:33:50,234 [Dummy-1:140337275598592] [django.db.backends:91] [utils:execute] [DEBUG]- (0.003) SELECT @@SQL_AUTO_IS_NULL; args=None
2018-06-28 22:33:50,237 [Dummy-1:140337275598592] [django.db.backends:91] [utils:execute] [DEBUG]- (0.003) SELECT VERSION(); args=None
2018-06-28 22:33:50,269 [Dummy-1:140337275598592] [django.db.backends:91] [utils:execute] [DEBUG]- (0.003) SHOW FULL TABLES; args=None
2018-06-28 22:33:50,288 [Dummy-1:140337275598592] [django.db.backends:91] [utils:execute] [DEBUG]- (0.003) SELECT `django_migrations`.`app`, `django_migrations`.`name` FROM `django_migrations`; args=()
2018-06-28 22:34:00,773 [Thread-2:140337263986432] [django.request:135] [exception:handle_uncaught_exception] [ERROR]- Internal Server Error: /email
Traceback (most recent call last):
  File "/usr/local/lib/python3.5/dist-packages/django/core/handlers/exception.py", line 41, in inner
    response = get_response(request)
  File "/usr/local/lib/python3.5/dist-packages/django/core/handlers/base.py", line 187, in _get_response
    response = self.process_exception_by_middleware(e, request)
  File "/usr/local/lib/python3.5/dist-packages/django/core/handlers/base.py", line 185, in _get_response
    response = wrapped_callback(request, *callback_args, **callback_kwargs)
  File "/root/teach1806/day08/t8/views.py", line 11, in send_my_mail
    send_mail(title,message,email_from,recs)
  File "/usr/local/lib/python3.5/dist-packages/django/core/mail/__init__.py", line 62, in send_mail
    return mail.send()
  File "/usr/local/lib/python3.5/dist-packages/django/core/mail/message.py", line 348, in send
    return self.get_connection(fail_silently).send_messages([self])
  File "/usr/local/lib/python3.5/dist-packages/django/core/mail/backends/smtp.py", line 111, in send_messages
    sent = self._send(message)
  File "/usr/local/lib/python3.5/dist-packages/django/core/mail/backends/smtp.py", line 127, in _send
    self.connection.sendmail(from_email, recipients, message.as_bytes(linesep='\r\n'))
  File "/usr/lib/python3.5/smtplib.py", line 883, in sendmail
    raise SMTPDataError(code, resp)
smtplib.SMTPDataError: (550, b'Error: content rejected.http://mail.qq.com/zh_CN/help/content/rejectedmail.html')
2018-06-28 22:34:00,773 [Thread-2:140337263986432] [django.request:135] [exception:handle_uncaught_exception] [ERROR]- Internal Server Error: /email
Traceback (most recent call last):
  File "/usr/local/lib/python3.5/dist-packages/django/core/handlers/exception.py", line 41, in inner
    response = get_response(request)
  File "/usr/local/lib/python3.5/dist-packages/django/core/handlers/base.py", line 187, in _get_response
    response = self.process_exception_by_middleware(e, request)
  File "/usr/local/lib/python3.5/dist-packages/django/core/handlers/base.py", line 185, in _get_response
    response = wrapped_callback(request, *callback_args, **callback_kwargs)
  File "/root/teach1806/day08/t8/views.py", line 11, in send_my_mail
    send_mail(title,message,email_from,recs)
  File "/usr/local/lib/python3.5/dist-packages/django/core/mail/__init__.py", line 62, in send_mail
    return mail.send()
  File "/usr/local/lib/python3.5/dist-packages/django/core/mail/message.py", line 348, in send
    return self.get_connection(fail_silently).send_messages([self])
  File "/usr/local/lib/python3.5/dist-packages/django/core/mail/backends/smtp.py", line 111, in send_messages
    sent = self._send(message)
  File "/usr/local/lib/python3.5/dist-packages/django/core/mail/backends/smtp.py", line 127, in _send
    self.connection.sendmail(from_email, recipients, message.as_bytes(linesep='\r\n'))
  File "/usr/lib/python3.5/smtplib.py", line 883, in sendmail
    raise SMTPDataError(code, resp)
smtplib.SMTPDataError: (550, b'Error: content rejected.http://mail.qq.com/zh_CN/help/content/rejectedmail.html')
2018-06-28 22:34:00,838 [Thread-2:140337263986432] [django.server:124] [basehttp:log_message] [ERROR]- "GET /email HTTP/1.1" 500 92090
2018-06-28 22:34:27,521 [Thread-5:140337263986432] [django.request:135] [exception:handle_uncaught_exception] [ERROR]- Internal Server Error: /email
Traceback (most recent call last):
  File "/usr/local/lib/python3.5/dist-packages/django/core/handlers/exception.py", line 41, in inner
    response = get_response(request)
  File "/usr/local/lib/python3.5/dist-packages/django/core/handlers/base.py", line 187, in _get_response
    response = self.process_exception_by_middleware(e, request)
  File "/usr/local/lib/python3.5/dist-packages/django/core/handlers/base.py", line 185, in _get_response
    response = wrapped_callback(request, *callback_args, **callback_kwargs)
  File "/root/teach1806/day08/t8/views.py", line 11, in send_my_mail
    send_mail(title,message,email_from,recs)
  File "/usr/local/lib/python3.5/dist-packages/django/core/mail/__init__.py", line 62, in send_mail
    return mail.send()
  File "/usr/local/lib/python3.5/dist-packages/django/core/mail/message.py", line 348, in send
    return self.get_connection(fail_silently).send_messages([self])
  File "/usr/local/lib/python3.5/dist-packages/django/core/mail/backends/smtp.py", line 111, in send_messages
    sent = self._send(message)
  File "/usr/local/lib/python3.5/dist-packages/django/core/mail/backends/smtp.py", line 127, in _send
    self.connection.sendmail(from_email, recipients, message.as_bytes(linesep='\r\n'))
  File "/usr/lib/python3.5/smtplib.py", line 883, in sendmail
    raise SMTPDataError(code, resp)
smtplib.SMTPDataError: (550, b'Error: content rejected.http://mail.qq.com/zh_CN/help/content/rejectedmail.html')
2018-06-28 22:34:27,521 [Thread-5:140337263986432] [django.request:135] [exception:handle_uncaught_exception] [ERROR]- Internal Server Error: /email
Traceback (most recent call last):
  File "/usr/local/lib/python3.5/dist-packages/django/core/handlers/exception.py", line 41, in inner
    response = get_response(request)
  File "/usr/local/lib/python3.5/dist-packages/django/core/handlers/base.py", line 187, in _get_response
    response = self.process_exception_by_middleware(e, request)
  File "/usr/local/lib/python3.5/dist-packages/django/core/handlers/base.py", line 185, in _get_response
    response = wrapped_callback(request, *callback_args, **callback_kwargs)
  File "/root/teach1806/day08/t8/views.py", line 11, in send_my_mail
    send_mail(title,message,email_from,recs)
  File "/usr/local/lib/python3.5/dist-packages/django/core/mail/__init__.py", line 62, in send_mail
    return mail.send()
  File "/usr/local/lib/python3.5/dist-packages/django/core/mail/message.py", line 348, in send
    return self.get_connection(fail_silently).send_messages([self])
  File "/usr/local/lib/python3.5/dist-packages/django/core/mail/backends/smtp.py", line 111, in send_messages
    sent = self._send(message)
  File "/usr/local/lib/python3.5/dist-packages/django/core/mail/backends/smtp.py", line 127, in _send
    self.connection.sendmail(from_email, recipients, message.as_bytes(linesep='\r\n'))
  File "/usr/lib/python3.5/smtplib.py", line 883, in sendmail
    raise SMTPDataError(code, resp)
smtplib.SMTPDataError: (550, b'Error: content rejected.http://mail.qq.com/zh_CN/help/content/rejectedmail.html')
2018-06-28 22:34:27,576 [Thread-5:140337263986432] [django.server:124] [basehttp:log_message] [ERROR]- "GET /email HTTP/1.1" 500 92225
2018-06-28 22:34:31,349 [Thread-4:140337183979264] [django.request:135] [exception:handle_uncaught_exception] [ERROR]- Internal Server Error: /email
Traceback (most recent call last):
  File "/usr/local/lib/python3.5/dist-packages/django/core/handlers/exception.py", line 41, in inner
    response = get_response(request)
  File "/usr/local/lib/python3.5/dist-packages/django/core/handlers/base.py", line 187, in _get_response
    response = self.process_exception_by_middleware(e, request)
  File "/usr/local/lib/python3.5/dist-packages/django/core/handlers/base.py", line 185, in _get_response
    response = wrapped_callback(request, *callback_args, **callback_kwargs)
  File "/root/teach1806/day08/t8/views.py", line 11, in send_my_mail
    send_mail(title,message,email_from,recs)
  File "/usr/local/lib/python3.5/dist-packages/django/core/mail/__init__.py", line 62, in send_mail
    return mail.send()
  File "/usr/local/lib/python3.5/dist-packages/django/core/mail/message.py", line 348, in send
    return self.get_connection(fail_silently).send_messages([self])
  File "/usr/local/lib/python3.5/dist-packages/django/core/mail/backends/smtp.py", line 111, in send_messages
    sent = self._send(message)
  File "/usr/local/lib/python3.5/dist-packages/django/core/mail/backends/smtp.py", line 127, in _send
    self.connection.sendmail(from_email, recipients, message.as_bytes(linesep='\r\n'))
  File "/usr/lib/python3.5/smtplib.py", line 883, in sendmail
    raise SMTPDataError(code, resp)
smtplib.SMTPDataError: (550, b'Error: content rejected.http://mail.qq.com/zh_CN/help/content/rejectedmail.html')
2018-06-28 22:34:31,349 [Thread-4:140337183979264] [django.request:135] [exception:handle_uncaught_exception] [ERROR]- Internal Server Error: /email
Traceback (most recent call last):
  File "/usr/local/lib/python3.5/dist-packages/django/core/handlers/exception.py", line 41, in inner
    response = get_response(request)
  File "/usr/local/lib/python3.5/dist-packages/django/core/handlers/base.py", line 187, in _get_response
    response = self.process_exception_by_middleware(e, request)
  File "/usr/local/lib/python3.5/dist-packages/django/core/handlers/base.py", line 185, in _get_response
    response = wrapped_callback(request, *callback_args, **callback_kwargs)
  File "/root/teach1806/day08/t8/views.py", line 11, in send_my_mail
    send_mail(title,message,email_from,recs)
  File "/usr/local/lib/python3.5/dist-packages/django/core/mail/__init__.py", line 62, in send_mail
    return mail.send()
  File "/usr/local/lib/python3.5/dist-packages/django/core/mail/message.py", line 348, in send
    return self.get_connection(fail_silently).send_messages([self])
  File "/usr/local/lib/python3.5/dist-packages/django/core/mail/backends/smtp.py", line 111, in send_messages
    sent = self._send(message)
  File "/usr/local/lib/python3.5/dist-packages/django/core/mail/backends/smtp.py", line 127, in _send
    self.connection.sendmail(from_email, recipients, message.as_bytes(linesep='\r\n'))
  File "/usr/lib/python3.5/smtplib.py", line 883, in sendmail
    raise SMTPDataError(code, resp)
smtplib.SMTPDataError: (550, b'Error: content rejected.http://mail.qq.com/zh_CN/help/content/rejectedmail.html')
2018-06-28 22:34:31,415 [Thread-4:140337183979264] [django.server:124] [basehttp:log_message] [ERROR]- "GET /email HTTP/1.1" 500 92351
2018-06-28 22:34:46,189 [Thread-7:140337263986432] [django.request:135] [exception:handle_uncaught_exception] [ERROR]- Internal Server Error: /htmlems
Traceback (most recent call last):
  File "/usr/local/lib/python3.5/dist-packages/django/core/handlers/exception.py", line 41, in inner
    response = get_response(request)
  File "/usr/local/lib/python3.5/dist-packages/django/core/handlers/base.py", line 187, in _get_response
    response = self.process_exception_by_middleware(e, request)
  File "/usr/local/lib/python3.5/dist-packages/django/core/handlers/base.py", line 185, in _get_response
    response = wrapped_callback(request, *callback_args, **callback_kwargs)
  File "/root/teach1806/day08/t8/views.py", line 11, in send_my_mail
    send_mail(title,message,email_from,recs)
  File "/usr/local/lib/python3.5/dist-packages/django/core/mail/__init__.py", line 62, in send_mail
    return mail.send()
  File "/usr/local/lib/python3.5/dist-packages/django/core/mail/message.py", line 348, in send
    return self.get_connection(fail_silently).send_messages([self])
  File "/usr/local/lib/python3.5/dist-packages/django/core/mail/backends/smtp.py", line 111, in send_messages
    sent = self._send(message)
  File "/usr/local/lib/python3.5/dist-packages/django/core/mail/backends/smtp.py", line 127, in _send
    self.connection.sendmail(from_email, recipients, message.as_bytes(linesep='\r\n'))
  File "/usr/lib/python3.5/smtplib.py", line 883, in sendmail
    raise SMTPDataError(code, resp)
smtplib.SMTPDataError: (550, b'Error: content rejected.http://mail.qq.com/zh_CN/help/content/rejectedmail.html')
2018-06-28 22:34:46,189 [Thread-7:140337263986432] [django.request:135] [exception:handle_uncaught_exception] [ERROR]- Internal Server Error: /htmlems
Traceback (most recent call last):
  File "/usr/local/lib/python3.5/dist-packages/django/core/handlers/exception.py", line 41, in inner
    response = get_response(request)
  File "/usr/local/lib/python3.5/dist-packages/django/core/handlers/base.py", line 187, in _get_response
    response = self.process_exception_by_middleware(e, request)
  File "/usr/local/lib/python3.5/dist-packages/django/core/handlers/base.py", line 185, in _get_response
    response = wrapped_callback(request, *callback_args, **callback_kwargs)
  File "/root/teach1806/day08/t8/views.py", line 11, in send_my_mail
    send_mail(title,message,email_from,recs)
  File "/usr/local/lib/python3.5/dist-packages/django/core/mail/__init__.py", line 62, in send_mail
    return mail.send()
  File "/usr/local/lib/python3.5/dist-packages/django/core/mail/message.py", line 348, in send
    return self.get_connection(fail_silently).send_messages([self])
  File "/usr/local/lib/python3.5/dist-packages/django/core/mail/backends/smtp.py", line 111, in send_messages
    sent = self._send(message)
  File "/usr/local/lib/python3.5/dist-packages/django/core/mail/backends/smtp.py", line 127, in _send
    self.connection.sendmail(from_email, recipients, message.as_bytes(linesep='\r\n'))
  File "/usr/lib/python3.5/smtplib.py", line 883, in sendmail
    raise SMTPDataError(code, resp)
smtplib.SMTPDataError: (550, b'Error: content rejected.http://mail.qq.com/zh_CN/help/content/rejectedmail.html')
2018-06-28 22:34:46,236 [Thread-7:140337263986432] [django.server:124] [basehttp:log_message] [ERROR]- "GET /htmlems HTTP/1.1" 500 92112
2018-06-28 22:39:40,826 [Dummy-1:140652663691008] [django.db.backends:91] [utils:execute] [DEBUG]- (0.002) SELECT @@SQL_AUTO_IS_NULL; args=None
2018-06-28 22:39:40,829 [Dummy-1:140652663691008] [django.db.backends:91] [utils:execute] [DEBUG]- (0.002) SELECT VERSION(); args=None
2018-06-28 22:39:40,860 [Dummy-1:140652663691008] [django.db.backends:91] [utils:execute] [DEBUG]- (0.002) SHOW FULL TABLES; args=None
2018-06-28 22:39:40,879 [Dummy-1:140652663691008] [django.db.backends:91] [utils:execute] [DEBUG]- (0.002) SELECT `django_migrations`.`app`, `django_migrations`.`name` FROM `django_migrations`; args=()
2018-06-28 22:39:47,632 [Thread-2:140652652078848] [django.request:135] [exception:handle_uncaught_exception] [ERROR]- Internal Server Error: /htmlems
Traceback (most recent call last):
  File "/usr/local/lib/python3.5/dist-packages/django/core/handlers/exception.py", line 41, in inner
    response = get_response(request)
  File "/usr/local/lib/python3.5/dist-packages/django/core/handlers/base.py", line 187, in _get_response
    response = self.process_exception_by_middleware(e, request)
  File "/usr/local/lib/python3.5/dist-packages/django/core/handlers/base.py", line 185, in _get_response
    response = wrapped_callback(request, *callback_args, **callback_kwargs)
  File "/root/teach1806/day08/t8/views.py", line 11, in send_my_mail
    send_mail(title,message,email_from,recs)
  File "/usr/local/lib/python3.5/dist-packages/django/core/mail/__init__.py", line 62, in send_mail
    return mail.send()
  File "/usr/local/lib/python3.5/dist-packages/django/core/mail/message.py", line 348, in send
    return self.get_connection(fail_silently).send_messages([self])
  File "/usr/local/lib/python3.5/dist-packages/django/core/mail/backends/smtp.py", line 111, in send_messages
    sent = self._send(message)
  File "/usr/local/lib/python3.5/dist-packages/django/core/mail/backends/smtp.py", line 127, in _send
    self.connection.sendmail(from_email, recipients, message.as_bytes(linesep='\r\n'))
  File "/usr/lib/python3.5/smtplib.py", line 883, in sendmail
    raise SMTPDataError(code, resp)
smtplib.SMTPDataError: (550, b'Error: content rejected.http://mail.qq.com/zh_CN/help/content/rejectedmail.html')
2018-06-28 22:39:47,632 [Thread-2:140652652078848] [django.request:135] [exception:handle_uncaught_exception] [ERROR]- Internal Server Error: /htmlems
Traceback (most recent call last):
  File "/usr/local/lib/python3.5/dist-packages/django/core/handlers/exception.py", line 41, in inner
    response = get_response(request)
  File "/usr/local/lib/python3.5/dist-packages/django/core/handlers/base.py", line 187, in _get_response
    response = self.process_exception_by_middleware(e, request)
  File "/usr/local/lib/python3.5/dist-packages/django/core/handlers/base.py", line 185, in _get_response
    response = wrapped_callback(request, *callback_args, **callback_kwargs)
  File "/root/teach1806/day08/t8/views.py", line 11, in send_my_mail
    send_mail(title,message,email_from,recs)
  File "/usr/local/lib/python3.5/dist-packages/django/core/mail/__init__.py", line 62, in send_mail
    return mail.send()
  File "/usr/local/lib/python3.5/dist-packages/django/core/mail/message.py", line 348, in send
    return self.get_connection(fail_silently).send_messages([self])
  File "/usr/local/lib/python3.5/dist-packages/django/core/mail/backends/smtp.py", line 111, in send_messages
    sent = self._send(message)
  File "/usr/local/lib/python3.5/dist-packages/django/core/mail/backends/smtp.py", line 127, in _send
    self.connection.sendmail(from_email, recipients, message.as_bytes(linesep='\r\n'))
  File "/usr/lib/python3.5/smtplib.py", line 883, in sendmail
    raise SMTPDataError(code, resp)
smtplib.SMTPDataError: (550, b'Error: content rejected.http://mail.qq.com/zh_CN/help/content/rejectedmail.html')
2018-06-28 22:39:47,703 [Thread-2:140652652078848] [django.server:124] [basehttp:log_message] [ERROR]- "GET /htmlems HTTP/1.1" 500 92373
2018-06-28 22:41:31,131 [Dummy-1:140112854750976] [django.db.backends:91] [utils:execute] [DEBUG]- (0.003) SELECT @@SQL_AUTO_IS_NULL; args=None
2018-06-28 22:41:31,134 [Dummy-1:140112854750976] [django.db.backends:91] [utils:execute] [DEBUG]- (0.003) SELECT VERSION(); args=None
2018-06-28 22:41:31,166 [Dummy-1:140112854750976] [django.db.backends:91] [utils:execute] [DEBUG]- (0.003) SHOW FULL TABLES; args=None
2018-06-28 22:41:31,186 [Dummy-1:140112854750976] [django.db.backends:91] [utils:execute] [DEBUG]- (0.003) SELECT `django_migrations`.`app`, `django_migrations`.`name` FROM `django_migrations`; args=()
2018-06-28 22:41:33,892 [Thread-2:140112771938048] [django.request:135] [exception:handle_uncaught_exception] [ERROR]- Internal Server Error: /htmlems
Traceback (most recent call last):
  File "/usr/local/lib/python3.5/dist-packages/django/core/handlers/exception.py", line 41, in inner
    response = get_response(request)
  File "/usr/local/lib/python3.5/dist-packages/django/core/handlers/base.py", line 187, in _get_response
    response = self.process_exception_by_middleware(e, request)
  File "/usr/local/lib/python3.5/dist-packages/django/core/handlers/base.py", line 185, in _get_response
    response = wrapped_callback(request, *callback_args, **callback_kwargs)
  File "/root/teach1806/day08/t8/views.py", line 11, in send_my_mail
    send_mail(title,message,email_from,recs)
  File "/usr/local/lib/python3.5/dist-packages/django/core/mail/__init__.py", line 62, in send_mail
    return mail.send()
  File "/usr/local/lib/python3.5/dist-packages/django/core/mail/message.py", line 348, in send
    return self.get_connection(fail_silently).send_messages([self])
  File "/usr/local/lib/python3.5/dist-packages/django/core/mail/backends/smtp.py", line 111, in send_messages
    sent = self._send(message)
  File "/usr/local/lib/python3.5/dist-packages/django/core/mail/backends/smtp.py", line 127, in _send
    self.connection.sendmail(from_email, recipients, message.as_bytes(linesep='\r\n'))
  File "/usr/lib/python3.5/smtplib.py", line 883, in sendmail
    raise SMTPDataError(code, resp)
smtplib.SMTPDataError: (550, b'Error: content rejected.http://mail.qq.com/zh_CN/help/content/rejectedmail.html')
2018-06-28 22:41:33,892 [Thread-2:140112771938048] [django.request:135] [exception:handle_uncaught_exception] [ERROR]- Internal Server Error: /htmlems
Traceback (most recent call last):
  File "/usr/local/lib/python3.5/dist-packages/django/core/handlers/exception.py", line 41, in inner
    response = get_response(request)
  File "/usr/local/lib/python3.5/dist-packages/django/core/handlers/base.py", line 187, in _get_response
    response = self.process_exception_by_middleware(e, request)
  File "/usr/local/lib/python3.5/dist-packages/django/core/handlers/base.py", line 185, in _get_response
    response = wrapped_callback(request, *callback_args, **callback_kwargs)
  File "/root/teach1806/day08/t8/views.py", line 11, in send_my_mail
    send_mail(title,message,email_from,recs)
  File "/usr/local/lib/python3.5/dist-packages/django/core/mail/__init__.py", line 62, in send_mail
    return mail.send()
  File "/usr/local/lib/python3.5/dist-packages/django/core/mail/message.py", line 348, in send
    return self.get_connection(fail_silently).send_messages([self])
  File "/usr/local/lib/python3.5/dist-packages/django/core/mail/backends/smtp.py", line 111, in send_messages
    sent = self._send(message)
  File "/usr/local/lib/python3.5/dist-packages/django/core/mail/backends/smtp.py", line 127, in _send
    self.connection.sendmail(from_email, recipients, message.as_bytes(linesep='\r\n'))
  File "/usr/lib/python3.5/smtplib.py", line 883, in sendmail
    raise SMTPDataError(code, resp)
smtplib.SMTPDataError: (550, b'Error: content rejected.http://mail.qq.com/zh_CN/help/content/rejectedmail.html')
2018-06-28 22:41:33,955 [Thread-2:140112771938048] [django.server:124] [basehttp:log_message] [ERROR]- "GET /htmlems HTTP/1.1" 500 92373
2018-06-28 22:42:25,676 [Thread-4:140112763545344] [django.request:135] [exception:handle_uncaught_exception] [ERROR]- Internal Server Error: /email
Traceback (most recent call last):
  File "/usr/local/lib/python3.5/dist-packages/django/core/handlers/exception.py", line 41, in inner
    response = get_response(request)
  File "/usr/local/lib/python3.5/dist-packages/django/core/handlers/base.py", line 187, in _get_response
    response = self.process_exception_by_middleware(e, request)
  File "/usr/local/lib/python3.5/dist-packages/django/core/handlers/base.py", line 185, in _get_response
    response = wrapped_callback(request, *callback_args, **callback_kwargs)
  File "/root/teach1806/day08/t8/views.py", line 11, in send_my_mail
    send_mail(title,message,email_from,recs)
  File "/usr/local/lib/python3.5/dist-packages/django/core/mail/__init__.py", line 62, in send_mail
    return mail.send()
  File "/usr/local/lib/python3.5/dist-packages/django/core/mail/message.py", line 348, in send
    return self.get_connection(fail_silently).send_messages([self])
  File "/usr/local/lib/python3.5/dist-packages/django/core/mail/backends/smtp.py", line 111, in send_messages
    sent = self._send(message)
  File "/usr/local/lib/python3.5/dist-packages/django/core/mail/backends/smtp.py", line 127, in _send
    self.connection.sendmail(from_email, recipients, message.as_bytes(linesep='\r\n'))
  File "/usr/lib/python3.5/smtplib.py", line 883, in sendmail
    raise SMTPDataError(code, resp)
smtplib.SMTPDataError: (550, b'Error: content rejected.http://mail.qq.com/zh_CN/help/content/rejectedmail.html')
2018-06-28 22:42:25,676 [Thread-4:140112763545344] [django.request:135] [exception:handle_uncaught_exception] [ERROR]- Internal Server Error: /email
Traceback (most recent call last):
  File "/usr/local/lib/python3.5/dist-packages/django/core/handlers/exception.py", line 41, in inner
    response = get_response(request)
  File "/usr/local/lib/python3.5/dist-packages/django/core/handlers/base.py", line 187, in _get_response
    response = self.process_exception_by_middleware(e, request)
  File "/usr/local/lib/python3.5/dist-packages/django/core/handlers/base.py", line 185, in _get_response
    response = wrapped_callback(request, *callback_args, **callback_kwargs)
  File "/root/teach1806/day08/t8/views.py", line 11, in send_my_mail
    send_mail(title,message,email_from,recs)
  File "/usr/local/lib/python3.5/dist-packages/django/core/mail/__init__.py", line 62, in send_mail
    return mail.send()
  File "/usr/local/lib/python3.5/dist-packages/django/core/mail/message.py", line 348, in send
    return self.get_connection(fail_silently).send_messages([self])
  File "/usr/local/lib/python3.5/dist-packages/django/core/mail/backends/smtp.py", line 111, in send_messages
    sent = self._send(message)
  File "/usr/local/lib/python3.5/dist-packages/django/core/mail/backends/smtp.py", line 127, in _send
    self.connection.sendmail(from_email, recipients, message.as_bytes(linesep='\r\n'))
  File "/usr/lib/python3.5/smtplib.py", line 883, in sendmail
    raise SMTPDataError(code, resp)
smtplib.SMTPDataError: (550, b'Error: content rejected.http://mail.qq.com/zh_CN/help/content/rejectedmail.html')
2018-06-28 22:42:25,722 [Thread-4:140112763545344] [django.server:124] [basehttp:log_message] [ERROR]- "GET /email HTTP/1.1" 500 92090
2018-06-28 22:45:56,310 [Dummy-1:140552932497152] [django.db.backends:91] [utils:execute] [DEBUG]- (0.002) SELECT @@SQL_AUTO_IS_NULL; args=None
2018-06-28 22:45:56,313 [Dummy-1:140552932497152] [django.db.backends:91] [utils:execute] [DEBUG]- (0.002) SELECT VERSION(); args=None
2018-06-28 22:45:56,347 [Dummy-1:140552932497152] [django.db.backends:91] [utils:execute] [DEBUG]- (0.002) SHOW FULL TABLES; args=None
2018-06-28 22:45:56,366 [Dummy-1:140552932497152] [django.db.backends:91] [utils:execute] [DEBUG]- (0.002) SELECT `django_migrations`.`app`, `django_migrations`.`name` FROM `django_migrations`; args=()
2018-06-28 22:45:59,609 [Thread-3:140552912492288] [django.request:135] [exception:handle_uncaught_exception] [ERROR]- Internal Server Error: /email
Traceback (most recent call last):
  File "/usr/local/lib/python3.5/dist-packages/django/core/handlers/exception.py", line 41, in inner
    response = get_response(request)
  File "/usr/local/lib/python3.5/dist-packages/django/core/handlers/base.py", line 187, in _get_response
    response = self.process_exception_by_middleware(e, request)
  File "/usr/local/lib/python3.5/dist-packages/django/core/handlers/base.py", line 185, in _get_response
    response = wrapped_callback(request, *callback_args, **callback_kwargs)
  File "/root/teach1806/day08/t8/views.py", line 11, in send_my_mail
    send_mail(title,message,email_from,recs)
  File "/usr/local/lib/python3.5/dist-packages/django/core/mail/__init__.py", line 62, in send_mail
    return mail.send()
  File "/usr/local/lib/python3.5/dist-packages/django/core/mail/message.py", line 348, in send
    return self.get_connection(fail_silently).send_messages([self])
  File "/usr/local/lib/python3.5/dist-packages/django/core/mail/backends/smtp.py", line 111, in send_messages
    sent = self._send(message)
  File "/usr/local/lib/python3.5/dist-packages/django/core/mail/backends/smtp.py", line 127, in _send
    self.connection.sendmail(from_email, recipients, message.as_bytes(linesep='\r\n'))
  File "/usr/lib/python3.5/smtplib.py", line 862, in sendmail
    raise SMTPSenderRefused(code, resp, from_addr)
smtplib.SMTPSenderRefused: (501, b'mail from address must be same as authorization user', '3369571193@qq.com')
2018-06-28 22:45:59,609 [Thread-3:140552912492288] [django.request:135] [exception:handle_uncaught_exception] [ERROR]- Internal Server Error: /email
Traceback (most recent call last):
  File "/usr/local/lib/python3.5/dist-packages/django/core/handlers/exception.py", line 41, in inner
    response = get_response(request)
  File "/usr/local/lib/python3.5/dist-packages/django/core/handlers/base.py", line 187, in _get_response
    response = self.process_exception_by_middleware(e, request)
  File "/usr/local/lib/python3.5/dist-packages/django/core/handlers/base.py", line 185, in _get_response
    response = wrapped_callback(request, *callback_args, **callback_kwargs)
  File "/root/teach1806/day08/t8/views.py", line 11, in send_my_mail
    send_mail(title,message,email_from,recs)
  File "/usr/local/lib/python3.5/dist-packages/django/core/mail/__init__.py", line 62, in send_mail
    return mail.send()
  File "/usr/local/lib/python3.5/dist-packages/django/core/mail/message.py", line 348, in send
    return self.get_connection(fail_silently).send_messages([self])
  File "/usr/local/lib/python3.5/dist-packages/django/core/mail/backends/smtp.py", line 111, in send_messages
    sent = self._send(message)
  File "/usr/local/lib/python3.5/dist-packages/django/core/mail/backends/smtp.py", line 127, in _send
    self.connection.sendmail(from_email, recipients, message.as_bytes(linesep='\r\n'))
  File "/usr/lib/python3.5/smtplib.py", line 862, in sendmail
    raise SMTPSenderRefused(code, resp, from_addr)
smtplib.SMTPSenderRefused: (501, b'mail from address must be same as authorization user', '3369571193@qq.com')
2018-06-28 22:45:59,673 [Thread-3:140552912492288] [django.server:124] [basehttp:log_message] [ERROR]- "GET /email HTTP/1.1" 500 91871
2018-06-28 22:46:55,507 [Dummy-1:139930591033088] [django.db.backends:91] [utils:execute] [DEBUG]- (0.003) SELECT @@SQL_AUTO_IS_NULL; args=None
2018-06-28 22:46:55,510 [Dummy-1:139930591033088] [django.db.backends:91] [utils:execute] [DEBUG]- (0.003) SELECT VERSION(); args=None
2018-06-28 22:46:55,547 [Dummy-1:139930591033088] [django.db.backends:91] [utils:execute] [DEBUG]- (0.003) SHOW FULL TABLES; args=None
2018-06-28 22:46:55,568 [Dummy-1:139930591033088] [django.db.backends:91] [utils:execute] [DEBUG]- (0.003) SELECT `django_migrations`.`app`, `django_migrations`.`name` FROM `django_migrations`; args=()
2018-06-28 22:47:21,082 [Dummy-1:140252677809920] [django.db.backends:91] [utils:execute] [DEBUG]- (0.002) SELECT @@SQL_AUTO_IS_NULL; args=None
2018-06-28 22:47:21,085 [Dummy-1:140252677809920] [django.db.backends:91] [utils:execute] [DEBUG]- (0.002) SELECT VERSION(); args=None
2018-06-28 22:47:21,120 [Dummy-1:140252677809920] [django.db.backends:91] [utils:execute] [DEBUG]- (0.002) SHOW FULL TABLES; args=None
2018-06-28 22:47:21,142 [Dummy-1:140252677809920] [django.db.backends:91] [utils:execute] [DEBUG]- (0.003) SELECT `django_migrations`.`app`, `django_migrations`.`name` FROM `django_migrations`; args=()
2018-06-28 22:47:24,653 [Thread-2:140252666197760] [django.server:124] [basehttp:log_message] [INFO]- "GET /email HTTP/1.1" 200 15
2018-06-28 22:49:39,659 [Dummy-1:140645440751360] [django.db.backends:91] [utils:execute] [DEBUG]- (0.002) SELECT @@SQL_AUTO_IS_NULL; args=None
2018-06-28 22:49:39,662 [Dummy-1:140645440751360] [django.db.backends:91] [utils:execute] [DEBUG]- (0.002) SELECT VERSION(); args=None
2018-06-28 22:49:39,699 [Dummy-1:140645440751360] [django.db.backends:91] [utils:execute] [DEBUG]- (0.003) SHOW FULL TABLES; args=None
2018-06-28 22:49:39,724 [Dummy-1:140645440751360] [django.db.backends:91] [utils:execute] [DEBUG]- (0.003) SELECT `django_migrations`.`app`, `django_migrations`.`name` FROM `django_migrations`; args=()
2018-06-28 22:49:49,106 [Dummy-1:140631062972160] [django.db.backends:91] [utils:execute] [DEBUG]- (0.002) SELECT @@SQL_AUTO_IS_NULL; args=None
2018-06-28 22:49:49,109 [Dummy-1:140631062972160] [django.db.backends:91] [utils:execute] [DEBUG]- (0.002) SELECT VERSION(); args=None
2018-06-28 22:49:49,142 [Dummy-1:140631062972160] [django.db.backends:91] [utils:execute] [DEBUG]- (0.003) SHOW FULL TABLES; args=None
2018-06-28 22:49:49,164 [Dummy-1:140631062972160] [django.db.backends:91] [utils:execute] [DEBUG]- (0.003) SELECT `django_migrations`.`app`, `django_migrations`.`name` FROM `django_migrations`; args=()
2018-06-28 22:49:56,203 [Thread-2:140630984152832] [django.request:135] [exception:handle_uncaught_exception] [ERROR]- Internal Server Error: /email
Traceback (most recent call last):
  File "/usr/local/lib/python3.5/dist-packages/django/core/handlers/exception.py", line 41, in inner
    response = get_response(request)
  File "/usr/local/lib/python3.5/dist-packages/django/core/handlers/base.py", line 187, in _get_response
    response = self.process_exception_by_middleware(e, request)
  File "/usr/local/lib/python3.5/dist-packages/django/core/handlers/base.py", line 185, in _get_response
    response = wrapped_callback(request, *callback_args, **callback_kwargs)
  File "/root/teach1806/day08/t8/views.py", line 11, in send_my_mail
    send_mail(title,message,email_from,recs)
  File "/usr/local/lib/python3.5/dist-packages/django/core/mail/__init__.py", line 62, in send_mail
    return mail.send()
  File "/usr/local/lib/python3.5/dist-packages/django/core/mail/message.py", line 348, in send
    return self.get_connection(fail_silently).send_messages([self])
  File "/usr/local/lib/python3.5/dist-packages/django/core/mail/backends/smtp.py", line 111, in send_messages
    sent = self._send(message)
  File "/usr/local/lib/python3.5/dist-packages/django/core/mail/backends/smtp.py", line 127, in _send
    self.connection.sendmail(from_email, recipients, message.as_bytes(linesep='\r\n'))
  File "/usr/lib/python3.5/smtplib.py", line 883, in sendmail
    raise SMTPDataError(code, resp)
smtplib.SMTPDataError: (550, b'Error: content rejected.http://mail.qq.com/zh_CN/help/content/rejectedmail.html')
2018-06-28 22:49:56,203 [Thread-2:140630984152832] [django.request:135] [exception:handle_uncaught_exception] [ERROR]- Internal Server Error: /email
Traceback (most recent call last):
  File "/usr/local/lib/python3.5/dist-packages/django/core/handlers/exception.py", line 41, in inner
    response = get_response(request)
  File "/usr/local/lib/python3.5/dist-packages/django/core/handlers/base.py", line 187, in _get_response
    response = self.process_exception_by_middleware(e, request)
  File "/usr/local/lib/python3.5/dist-packages/django/core/handlers/base.py", line 185, in _get_response
    response = wrapped_callback(request, *callback_args, **callback_kwargs)
  File "/root/teach1806/day08/t8/views.py", line 11, in send_my_mail
    send_mail(title,message,email_from,recs)
  File "/usr/local/lib/python3.5/dist-packages/django/core/mail/__init__.py", line 62, in send_mail
    return mail.send()
  File "/usr/local/lib/python3.5/dist-packages/django/core/mail/message.py", line 348, in send
    return self.get_connection(fail_silently).send_messages([self])
  File "/usr/local/lib/python3.5/dist-packages/django/core/mail/backends/smtp.py", line 111, in send_messages
    sent = self._send(message)
  File "/usr/local/lib/python3.5/dist-packages/django/core/mail/backends/smtp.py", line 127, in _send
    self.connection.sendmail(from_email, recipients, message.as_bytes(linesep='\r\n'))
  File "/usr/lib/python3.5/smtplib.py", line 883, in sendmail
    raise SMTPDataError(code, resp)
smtplib.SMTPDataError: (550, b'Error: content rejected.http://mail.qq.com/zh_CN/help/content/rejectedmail.html')
2018-06-28 22:49:56,265 [Thread-2:140630984152832] [django.server:124] [basehttp:log_message] [ERROR]- "GET /email HTTP/1.1" 500 92351
2018-06-28 22:51:01,104 [Dummy-1:140323859703552] [django.db.backends:91] [utils:execute] [DEBUG]- (0.002) SELECT @@SQL_AUTO_IS_NULL; args=None
2018-06-28 22:51:01,106 [Dummy-1:140323859703552] [django.db.backends:91] [utils:execute] [DEBUG]- (0.002) SELECT VERSION(); args=None
2018-06-28 22:51:01,145 [Dummy-1:140323859703552] [django.db.backends:91] [utils:execute] [DEBUG]- (0.003) SHOW FULL TABLES; args=None
2018-06-28 22:51:01,168 [Dummy-1:140323859703552] [django.db.backends:91] [utils:execute] [DEBUG]- (0.003) SELECT `django_migrations`.`app`, `django_migrations`.`name` FROM `django_migrations`; args=()
2018-06-28 22:51:39,822 [Thread-3:140323839698688] [django.request:135] [exception:handle_uncaught_exception] [ERROR]- Internal Server Error: /email
Traceback (most recent call last):
  File "/usr/local/lib/python3.5/dist-packages/django/core/handlers/exception.py", line 41, in inner
    response = get_response(request)
  File "/usr/local/lib/python3.5/dist-packages/django/core/handlers/base.py", line 187, in _get_response
    response = self.process_exception_by_middleware(e, request)
  File "/usr/local/lib/python3.5/dist-packages/django/core/handlers/base.py", line 185, in _get_response
    response = wrapped_callback(request, *callback_args, **callback_kwargs)
  File "/root/teach1806/day08/t8/views.py", line 11, in send_my_mail
    send_mail(title,message,email_from,recs)
  File "/usr/local/lib/python3.5/dist-packages/django/core/mail/__init__.py", line 62, in send_mail
    return mail.send()
  File "/usr/local/lib/python3.5/dist-packages/django/core/mail/message.py", line 348, in send
    return self.get_connection(fail_silently).send_messages([self])
  File "/usr/local/lib/python3.5/dist-packages/django/core/mail/backends/smtp.py", line 111, in send_messages
    sent = self._send(message)
  File "/usr/local/lib/python3.5/dist-packages/django/core/mail/backends/smtp.py", line 127, in _send
    self.connection.sendmail(from_email, recipients, message.as_bytes(linesep='\r\n'))
  File "/usr/lib/python3.5/smtplib.py", line 883, in sendmail
    raise SMTPDataError(code, resp)
smtplib.SMTPDataError: (550, b'Error: content rejected.http://mail.qq.com/zh_CN/help/content/rejectedmail.html')
2018-06-28 22:51:39,822 [Thread-3:140323839698688] [django.request:135] [exception:handle_uncaught_exception] [ERROR]- Internal Server Error: /email
Traceback (most recent call last):
  File "/usr/local/lib/python3.5/dist-packages/django/core/handlers/exception.py", line 41, in inner
    response = get_response(request)
  File "/usr/local/lib/python3.5/dist-packages/django/core/handlers/base.py", line 187, in _get_response
    response = self.process_exception_by_middleware(e, request)
  File "/usr/local/lib/python3.5/dist-packages/django/core/handlers/base.py", line 185, in _get_response
    response = wrapped_callback(request, *callback_args, **callback_kwargs)
  File "/root/teach1806/day08/t8/views.py", line 11, in send_my_mail
    send_mail(title,message,email_from,recs)
  File "/usr/local/lib/python3.5/dist-packages/django/core/mail/__init__.py", line 62, in send_mail
    return mail.send()
  File "/usr/local/lib/python3.5/dist-packages/django/core/mail/message.py", line 348, in send
    return self.get_connection(fail_silently).send_messages([self])
  File "/usr/local/lib/python3.5/dist-packages/django/core/mail/backends/smtp.py", line 111, in send_messages
    sent = self._send(message)
  File "/usr/local/lib/python3.5/dist-packages/django/core/mail/backends/smtp.py", line 127, in _send
    self.connection.sendmail(from_email, recipients, message.as_bytes(linesep='\r\n'))
  File "/usr/lib/python3.5/smtplib.py", line 883, in sendmail
    raise SMTPDataError(code, resp)
smtplib.SMTPDataError: (550, b'Error: content rejected.http://mail.qq.com/zh_CN/help/content/rejectedmail.html')
2018-06-28 22:51:39,899 [Thread-3:140323839698688] [django.server:124] [basehttp:log_message] [ERROR]- "GET /email HTTP/1.1" 500 92351
2018-06-28 23:52:55,776 [Thread-4:140323848091392] [django.template:925] [base:_resolve_lookup] [DEBUG]- Exception while resolving variable 'name' in template 'unknown'.
Traceback (most recent call last):
  File "/usr/local/lib/python3.5/dist-packages/django/core/handlers/exception.py", line 41, in inner
    response = get_response(request)
  File "/usr/local/lib/python3.5/dist-packages/django/core/handlers/base.py", line 172, in _get_response
    resolver_match = resolver.resolve(request.path_info)
  File "/usr/local/lib/python3.5/dist-packages/django/urls/resolvers.py", line 392, in resolve
    raise Resolver404({'tried': tried, 'path': new_path})
django.urls.exceptions.Resolver404: {'path': '', 'tried': [[<RegexURLResolver <RegexURLPattern list> (admin:admin) ^admin/>], [<RegexURLPattern None ^email$>], [<RegexURLPattern None ^ems$>], [<RegexURLPattern None ^htmlems$>], [<RegexURLPattern None ^text$>], [<RegexURLPattern None ^verify/(.+)>]]}

During handling of the above exception, another exception occurred:

Traceback (most recent call last):
  File "/usr/local/lib/python3.5/dist-packages/django/template/base.py", line 882, in _resolve_lookup
    current = current[bit]
TypeError: 'RegexURLResolver' object is not subscriptable

During handling of the above exception, another exception occurred:

Traceback (most recent call last):
  File "/usr/local/lib/python3.5/dist-packages/django/template/base.py", line 890, in _resolve_lookup
    current = getattr(current, bit)
AttributeError: 'RegexURLResolver' object has no attribute 'name'

During handling of the above exception, another exception occurred:

Traceback (most recent call last):
  File "/usr/local/lib/python3.5/dist-packages/django/template/base.py", line 896, in _resolve_lookup
    current = current[int(bit)]
ValueError: invalid literal for int() with base 10: 'name'

During handling of the above exception, another exception occurred:

Traceback (most recent call last):
  File "/usr/local/lib/python3.5/dist-packages/django/template/base.py", line 903, in _resolve_lookup
    (bit, current))  # missing attribute
django.template.base.VariableDoesNotExist: Failed lookup for key [name] in '<RegexURLResolver <RegexURLPattern list> (admin:admin) ^admin/>'
2018-06-28 23:52:55,779 [Thread-4:140323848091392] [django.server:124] [basehttp:log_message] [WARNING]- "GET / HTTP/1.1" 404 2455
